[rospy.client][INFO] 2020-02-27 10:00:30,574: init_node, name[/serial_node], pid[25687]
[xmlrpc][INFO] 2020-02-27 10:00:30,575: XML-RPC server binding to 0.0.0.0:0
[xmlrpc][INFO] 2020-02-27 10:00:30,575: Started XML-RPC server [http://itachi-HP-Pavilion-Laptop-15-cc1xx:41441/]
[rospy.init][INFO] 2020-02-27 10:00:30,575: ROS Slave URI: [http://itachi-HP-Pavilion-Laptop-15-cc1xx:41441/]
[rospy.impl.masterslave][INFO] 2020-02-27 10:00:30,575: _ready: http://itachi-HP-Pavilion-Laptop-15-cc1xx:41441/
[rospy.registration][INFO] 2020-02-27 10:00:30,576: Registering with master node http://localhost:11311
[xmlrpc][INFO] 2020-02-27 10:00:30,576: xml rpc node: starting XML-RPC server
[rospy.init][INFO] 2020-02-27 10:00:30,676: registered with master
[rospy.rosout][INFO] 2020-02-27 10:00:30,676: initializing /rosout core topic
[rospy.rosout][INFO] 2020-02-27 10:00:30,684: connected to core topic /rosout
[rospy.simtime][INFO] 2020-02-27 10:00:30,687: /use_sim_time is not set, will not subscribe to simulated time [/clock] topic
[rosout][INFO] 2020-02-27 10:00:30,695: ROS Serial Python Node
[rosout][INFO] 2020-02-27 10:00:30,711: Connecting to /dev/ttyUSB0 at 115200 baud
[rospy.internal][INFO] 2020-02-27 10:00:30,948: topic[/rosout] adding connection to [/rosout], count 0
[rosout][INFO] 2020-02-27 10:00:32,835: Note: subscribe buffer size is 320 bytes
[rosout][INFO] 2020-02-27 10:00:32,835: Setup subscriber on led_control_topic [std_msgs/Int8]
[rospy.internal][INFO] 2020-02-27 10:01:11,626: topic[/led_control_topic] adding connection to [http://itachi-HP-Pavilion-Laptop-15-cc1xx:43673/], count 0
[rospy.internal][ERROR] 2020-02-27 10:02:12,027: Unable to initiate TCP/IP socket to itachi-HP-Pavilion-Laptop-15-cc1xx:35519 (http://itachi-HP-Pavilion-Laptop-15-cc1xx:43673/): Traceback (most recent call last):
  File "/opt/ros/kinetic/lib/python2.7/dist-packages/rospy/impl/tcpros_base.py", line 557, in connect
    self.read_header()
  File "/opt/ros/kinetic/lib/python2.7/dist-packages/rospy/impl/tcpros_base.py", line 650, in read_header
    self._validate_header(read_ros_handshake_header(sock, self.read_buff, self.protocol.buff_size))
  File "/opt/ros/kinetic/lib/python2.7/dist-packages/rospy/impl/tcpros_base.py", line 593, in _validate_header
    raise TransportInitError("remote error reported: %s"%header['error'])
TransportInitError: remote error reported: node shutting down

[rospy.internal][WARNING] 2020-02-27 10:02:13,028: Unknown error initiating TCP/IP socket to itachi-HP-Pavilion-Laptop-15-cc1xx:35519 (http://itachi-HP-Pavilion-Laptop-15-cc1xx:43673/): Traceback (most recent call last):
  File "/opt/ros/kinetic/lib/python2.7/dist-packages/rospy/impl/tcpros_base.py", line 555, in connect
    self.socket.connect((dest_addr, dest_port))
  File "/usr/lib/python2.7/socket.py", line 228, in meth
    return getattr(self._sock,name)(*args)
error: [Errno 111] Connection refused

[rospy.internal][INFO] 2020-02-27 10:02:13,029: topic[/led_control_topic] removing connection to http://itachi-HP-Pavilion-Laptop-15-cc1xx:43673/
[rospy.internal][INFO] 2020-02-27 10:03:26,199: topic[/led_control_topic] adding connection to [http://itachi-HP-Pavilion-Laptop-15-cc1xx:39303/], count 0
[rospy.internal][ERROR] 2020-02-27 10:06:29,933: Unable to initiate TCP/IP socket to itachi-HP-Pavilion-Laptop-15-cc1xx:44541 (http://itachi-HP-Pavilion-Laptop-15-cc1xx:39303/): Traceback (most recent call last):
  File "/opt/ros/kinetic/lib/python2.7/dist-packages/rospy/impl/tcpros_base.py", line 557, in connect
    self.read_header()
  File "/opt/ros/kinetic/lib/python2.7/dist-packages/rospy/impl/tcpros_base.py", line 650, in read_header
    self._validate_header(read_ros_handshake_header(sock, self.read_buff, self.protocol.buff_size))
  File "/opt/ros/kinetic/lib/python2.7/dist-packages/rospy/impl/tcpros_base.py", line 593, in _validate_header
    raise TransportInitError("remote error reported: %s"%header['error'])
TransportInitError: remote error reported: node shutting down

[rospy.internal][WARNING] 2020-02-27 10:06:30,936: Unknown error initiating TCP/IP socket to itachi-HP-Pavilion-Laptop-15-cc1xx:44541 (http://itachi-HP-Pavilion-Laptop-15-cc1xx:39303/): Traceback (most recent call last):
  File "/opt/ros/kinetic/lib/python2.7/dist-packages/rospy/impl/tcpros_base.py", line 555, in connect
    self.socket.connect((dest_addr, dest_port))
  File "/usr/lib/python2.7/socket.py", line 228, in meth
    return getattr(self._sock,name)(*args)
error: [Errno 111] Connection refused

[rospy.internal][INFO] 2020-02-27 10:06:30,936: topic[/led_control_topic] removing connection to http://itachi-HP-Pavilion-Laptop-15-cc1xx:39303/
[rospy.internal][INFO] 2020-02-27 10:07:36,062: topic[/led_control_topic] adding connection to [http://itachi-HP-Pavilion-Laptop-15-cc1xx:41673/], count 0
[rospy.internal][WARNING] 2020-02-27 10:10:39,283: Unknown error initiating TCP/IP socket to itachi-HP-Pavilion-Laptop-15-cc1xx:42161 (http://itachi-HP-Pavilion-Laptop-15-cc1xx:41673/): Traceback (most recent call last):
  File "/opt/ros/kinetic/lib/python2.7/dist-packages/rospy/impl/tcpros_base.py", line 557, in connect
    self.read_header()
  File "/opt/ros/kinetic/lib/python2.7/dist-packages/rospy/impl/tcpros_base.py", line 650, in read_header
    self._validate_header(read_ros_handshake_header(sock, self.read_buff, self.protocol.buff_size))
  File "/opt/ros/kinetic/lib/python2.7/dist-packages/rosgraph/network.py", line 362, in read_ros_handshake_header
    d = sock.recv(buff_size)
error: [Errno 104] Connection reset by peer

[rospy.internal][INFO] 2020-02-27 10:10:39,283: topic[/led_control_topic] removing connection to http://itachi-HP-Pavilion-Laptop-15-cc1xx:41673/
[rospy.internal][INFO] 2020-02-27 10:11:36,671: topic[/led_control_topic] adding connection to [http://itachi-HP-Pavilion-Laptop-15-cc1xx:38231/], count 0
[rospy.internal][ERROR] 2020-02-27 10:14:39,920: Unable to initiate TCP/IP socket to itachi-HP-Pavilion-Laptop-15-cc1xx:34313 (http://itachi-HP-Pavilion-Laptop-15-cc1xx:38231/): Traceback (most recent call last):
  File "/opt/ros/kinetic/lib/python2.7/dist-packages/rospy/impl/tcpros_base.py", line 557, in connect
    self.read_header()
  File "/opt/ros/kinetic/lib/python2.7/dist-packages/rospy/impl/tcpros_base.py", line 650, in read_header
    self._validate_header(read_ros_handshake_header(sock, self.read_buff, self.protocol.buff_size))
  File "/opt/ros/kinetic/lib/python2.7/dist-packages/rospy/impl/tcpros_base.py", line 593, in _validate_header
    raise TransportInitError("remote error reported: %s"%header['error'])
TransportInitError: remote error reported: node shutting down

[rospy.internal][WARNING] 2020-02-27 10:14:40,923: Unknown error initiating TCP/IP socket to itachi-HP-Pavilion-Laptop-15-cc1xx:34313 (http://itachi-HP-Pavilion-Laptop-15-cc1xx:38231/): Traceback (most recent call last):
  File "/opt/ros/kinetic/lib/python2.7/dist-packages/rospy/impl/tcpros_base.py", line 555, in connect
    self.socket.connect((dest_addr, dest_port))
  File "/usr/lib/python2.7/socket.py", line 228, in meth
    return getattr(self._sock,name)(*args)
error: [Errno 111] Connection refused

[rospy.internal][INFO] 2020-02-27 10:14:40,924: topic[/led_control_topic] removing connection to http://itachi-HP-Pavilion-Laptop-15-cc1xx:38231/
[rosout][INFO] 2020-02-27 10:28:06,284: Send tx stop request
[rospy.core][INFO] 2020-02-27 10:28:06,286: signal_shutdown [atexit]
[rospy.internal][INFO] 2020-02-27 10:28:06,294: topic[/rosout] removing connection to /rosout
[rospy.impl.masterslave][INFO] 2020-02-27 10:28:06,294: atexit
