[rospy.client][INFO] 2020-02-27 12:45:33,362: init_node, name[/serial_node], pid[12470]
[xmlrpc][INFO] 2020-02-27 12:45:33,363: XML-RPC server binding to 0.0.0.0:0
[xmlrpc][INFO] 2020-02-27 12:45:33,365: Started XML-RPC server [http://itachi-HP-Pavilion-Laptop-15-cc1xx:38195/]
[rospy.impl.masterslave][INFO] 2020-02-27 12:45:33,366: _ready: http://itachi-HP-Pavilion-Laptop-15-cc1xx:38195/
[xmlrpc][INFO] 2020-02-27 12:45:33,367: xml rpc node: starting XML-RPC server
[rospy.init][INFO] 2020-02-27 12:45:33,367: ROS Slave URI: [http://itachi-HP-Pavilion-Laptop-15-cc1xx:38195/]
[rospy.registration][INFO] 2020-02-27 12:45:33,369: Registering with master node http://localhost:11311
[rospy.init][INFO] 2020-02-27 12:45:33,468: registered with master
[rospy.rosout][INFO] 2020-02-27 12:45:33,468: initializing /rosout core topic
[rospy.rosout][INFO] 2020-02-27 12:45:33,470: connected to core topic /rosout
[rospy.simtime][INFO] 2020-02-27 12:45:33,471: /use_sim_time is not set, will not subscribe to simulated time [/clock] topic
[rosout][INFO] 2020-02-27 12:45:33,474: ROS Serial Python Node
[rosout][INFO] 2020-02-27 12:45:33,479: Connecting to /dev/ttyUSB0 at 115200 baud
[rospy.internal][INFO] 2020-02-27 12:45:33,709: topic[/rosout] adding connection to [/rosout], count 0
[rosout][INFO] 2020-02-27 12:45:35,600: Note: subscribe buffer size is 320 bytes
[rosout][INFO] 2020-02-27 12:45:35,600: Setup subscriber on led_control_topic [std_msgs/Int8]
[rospy.internal][INFO] 2020-02-27 12:46:45,096: topic[/led_control_topic] adding connection to [http://itachi-HP-Pavilion-Laptop-15-cc1xx:38713/], count 0
[rospy.internal][WARNING] 2020-02-27 12:47:34,592: Unknown error initiating TCP/IP socket to itachi-HP-Pavilion-Laptop-15-cc1xx:41405 (http://itachi-HP-Pavilion-Laptop-15-cc1xx:38713/): Traceback (most recent call last):
  File "/opt/ros/kinetic/lib/python2.7/dist-packages/rospy/impl/tcpros_base.py", line 557, in connect
    self.read_header()
  File "/opt/ros/kinetic/lib/python2.7/dist-packages/rospy/impl/tcpros_base.py", line 650, in read_header
    self._validate_header(read_ros_handshake_header(sock, self.read_buff, self.protocol.buff_size))
  File "/opt/ros/kinetic/lib/python2.7/dist-packages/rosgraph/network.py", line 362, in read_ros_handshake_header
    d = sock.recv(buff_size)
error: [Errno 104] Connection reset by peer

[rospy.internal][INFO] 2020-02-27 12:47:34,593: topic[/led_control_topic] removing connection to http://itachi-HP-Pavilion-Laptop-15-cc1xx:38713/
[rospy.internal][INFO] 2020-02-27 12:47:39,287: topic[/led_control_topic] adding connection to [http://itachi-HP-Pavilion-Laptop-15-cc1xx:42465/], count 0
[rospy.internal][ERROR] 2020-02-27 12:49:37,455: Unable to initiate TCP/IP socket to itachi-HP-Pavilion-Laptop-15-cc1xx:35451 (http://itachi-HP-Pavilion-Laptop-15-cc1xx:42465/): Traceback (most recent call last):
  File "/opt/ros/kinetic/lib/python2.7/dist-packages/rospy/impl/tcpros_base.py", line 557, in connect
    self.read_header()
  File "/opt/ros/kinetic/lib/python2.7/dist-packages/rospy/impl/tcpros_base.py", line 650, in read_header
    self._validate_header(read_ros_handshake_header(sock, self.read_buff, self.protocol.buff_size))
  File "/opt/ros/kinetic/lib/python2.7/dist-packages/rospy/impl/tcpros_base.py", line 593, in _validate_header
    raise TransportInitError("remote error reported: %s"%header['error'])
TransportInitError: remote error reported: node shutting down

[rospy.internal][WARNING] 2020-02-27 12:49:38,457: Unknown error initiating TCP/IP socket to itachi-HP-Pavilion-Laptop-15-cc1xx:35451 (http://itachi-HP-Pavilion-Laptop-15-cc1xx:42465/): Traceback (most recent call last):
  File "/opt/ros/kinetic/lib/python2.7/dist-packages/rospy/impl/tcpros_base.py", line 555, in connect
    self.socket.connect((dest_addr, dest_port))
  File "/usr/lib/python2.7/socket.py", line 228, in meth
    return getattr(self._sock,name)(*args)
error: [Errno 111] Connection refused

[rospy.internal][INFO] 2020-02-27 12:49:38,457: topic[/led_control_topic] removing connection to http://itachi-HP-Pavilion-Laptop-15-cc1xx:42465/
[rospy.internal][INFO] 2020-02-27 12:49:40,827: topic[/led_control_topic] adding connection to [http://itachi-HP-Pavilion-Laptop-15-cc1xx:34579/], count 0
[rospy.internal][WARNING] 2020-02-27 12:50:17,984: Unknown error initiating TCP/IP socket to itachi-HP-Pavilion-Laptop-15-cc1xx:39327 (http://itachi-HP-Pavilion-Laptop-15-cc1xx:34579/): Traceback (most recent call last):
  File "/opt/ros/kinetic/lib/python2.7/dist-packages/rospy/impl/tcpros_base.py", line 557, in connect
    self.read_header()
  File "/opt/ros/kinetic/lib/python2.7/dist-packages/rospy/impl/tcpros_base.py", line 650, in read_header
    self._validate_header(read_ros_handshake_header(sock, self.read_buff, self.protocol.buff_size))
  File "/opt/ros/kinetic/lib/python2.7/dist-packages/rosgraph/network.py", line 362, in read_ros_handshake_header
    d = sock.recv(buff_size)
error: [Errno 104] Connection reset by peer

[rospy.internal][INFO] 2020-02-27 12:50:17,984: topic[/led_control_topic] removing connection to http://itachi-HP-Pavilion-Laptop-15-cc1xx:34579/
[rospy.internal][INFO] 2020-02-27 12:50:22,848: topic[/led_control_topic] adding connection to [http://itachi-HP-Pavilion-Laptop-15-cc1xx:38753/], count 0
[rospy.internal][ERROR] 2020-02-27 12:51:11,711: Unable to initiate TCP/IP socket to itachi-HP-Pavilion-Laptop-15-cc1xx:36589 (http://itachi-HP-Pavilion-Laptop-15-cc1xx:38753/): Traceback (most recent call last):
  File "/opt/ros/kinetic/lib/python2.7/dist-packages/rospy/impl/tcpros_base.py", line 557, in connect
    self.read_header()
  File "/opt/ros/kinetic/lib/python2.7/dist-packages/rospy/impl/tcpros_base.py", line 650, in read_header
    self._validate_header(read_ros_handshake_header(sock, self.read_buff, self.protocol.buff_size))
  File "/opt/ros/kinetic/lib/python2.7/dist-packages/rospy/impl/tcpros_base.py", line 593, in _validate_header
    raise TransportInitError("remote error reported: %s"%header['error'])
TransportInitError: remote error reported: node shutting down

[rospy.internal][WARNING] 2020-02-27 12:51:12,712: Unknown error initiating TCP/IP socket to itachi-HP-Pavilion-Laptop-15-cc1xx:36589 (http://itachi-HP-Pavilion-Laptop-15-cc1xx:38753/): Traceback (most recent call last):
  File "/opt/ros/kinetic/lib/python2.7/dist-packages/rospy/impl/tcpros_base.py", line 555, in connect
    self.socket.connect((dest_addr, dest_port))
  File "/usr/lib/python2.7/socket.py", line 228, in meth
    return getattr(self._sock,name)(*args)
error: [Errno 111] Connection refused

[rospy.internal][INFO] 2020-02-27 12:51:12,713: topic[/led_control_topic] removing connection to http://itachi-HP-Pavilion-Laptop-15-cc1xx:38753/
[rospy.internal][INFO] 2020-02-27 12:51:14,801: topic[/led_control_topic] adding connection to [http://itachi-HP-Pavilion-Laptop-15-cc1xx:37807/], count 0
[rospy.internal][ERROR] 2020-02-27 12:54:14,914: Unable to initiate TCP/IP socket to itachi-HP-Pavilion-Laptop-15-cc1xx:41009 (http://itachi-HP-Pavilion-Laptop-15-cc1xx:37807/): Traceback (most recent call last):
  File "/opt/ros/kinetic/lib/python2.7/dist-packages/rospy/impl/tcpros_base.py", line 557, in connect
    self.read_header()
  File "/opt/ros/kinetic/lib/python2.7/dist-packages/rospy/impl/tcpros_base.py", line 650, in read_header
    self._validate_header(read_ros_handshake_header(sock, self.read_buff, self.protocol.buff_size))
  File "/opt/ros/kinetic/lib/python2.7/dist-packages/rospy/impl/tcpros_base.py", line 593, in _validate_header
    raise TransportInitError("remote error reported: %s"%header['error'])
TransportInitError: remote error reported: node shutting down

[rospy.internal][WARNING] 2020-02-27 12:54:15,915: Unknown error initiating TCP/IP socket to itachi-HP-Pavilion-Laptop-15-cc1xx:41009 (http://itachi-HP-Pavilion-Laptop-15-cc1xx:37807/): Traceback (most recent call last):
  File "/opt/ros/kinetic/lib/python2.7/dist-packages/rospy/impl/tcpros_base.py", line 555, in connect
    self.socket.connect((dest_addr, dest_port))
  File "/usr/lib/python2.7/socket.py", line 228, in meth
    return getattr(self._sock,name)(*args)
error: [Errno 111] Connection refused

[rospy.internal][INFO] 2020-02-27 12:54:15,915: topic[/led_control_topic] removing connection to http://itachi-HP-Pavilion-Laptop-15-cc1xx:37807/
[rospy.internal][INFO] 2020-02-27 12:54:17,834: topic[/led_control_topic] adding connection to [http://itachi-HP-Pavilion-Laptop-15-cc1xx:32963/], count 0
[rospy.internal][ERROR] 2020-02-27 12:56:26,295: Unable to initiate TCP/IP socket to itachi-HP-Pavilion-Laptop-15-cc1xx:45509 (http://itachi-HP-Pavilion-Laptop-15-cc1xx:32963/): Traceback (most recent call last):
  File "/opt/ros/kinetic/lib/python2.7/dist-packages/rospy/impl/tcpros_base.py", line 557, in connect
    self.read_header()
  File "/opt/ros/kinetic/lib/python2.7/dist-packages/rospy/impl/tcpros_base.py", line 650, in read_header
    self._validate_header(read_ros_handshake_header(sock, self.read_buff, self.protocol.buff_size))
  File "/opt/ros/kinetic/lib/python2.7/dist-packages/rospy/impl/tcpros_base.py", line 593, in _validate_header
    raise TransportInitError("remote error reported: %s"%header['error'])
TransportInitError: remote error reported: node shutting down

[rospy.internal][WARNING] 2020-02-27 12:56:27,297: Unknown error initiating TCP/IP socket to itachi-HP-Pavilion-Laptop-15-cc1xx:45509 (http://itachi-HP-Pavilion-Laptop-15-cc1xx:32963/): Traceback (most recent call last):
  File "/opt/ros/kinetic/lib/python2.7/dist-packages/rospy/impl/tcpros_base.py", line 555, in connect
    self.socket.connect((dest_addr, dest_port))
  File "/usr/lib/python2.7/socket.py", line 228, in meth
    return getattr(self._sock,name)(*args)
error: [Errno 111] Connection refused

[rospy.internal][INFO] 2020-02-27 12:56:27,297: topic[/led_control_topic] removing connection to http://itachi-HP-Pavilion-Laptop-15-cc1xx:32963/
[rospy.internal][INFO] 2020-02-27 12:56:29,185: topic[/led_control_topic] adding connection to [http://itachi-HP-Pavilion-Laptop-15-cc1xx:35551/], count 0
[rospy.internal][WARNING] 2020-02-27 12:57:13,974: Unknown error initiating TCP/IP socket to itachi-HP-Pavilion-Laptop-15-cc1xx:46225 (http://itachi-HP-Pavilion-Laptop-15-cc1xx:35551/): Traceback (most recent call last):
  File "/opt/ros/kinetic/lib/python2.7/dist-packages/rospy/impl/tcpros_base.py", line 557, in connect
    self.read_header()
  File "/opt/ros/kinetic/lib/python2.7/dist-packages/rospy/impl/tcpros_base.py", line 650, in read_header
    self._validate_header(read_ros_handshake_header(sock, self.read_buff, self.protocol.buff_size))
  File "/opt/ros/kinetic/lib/python2.7/dist-packages/rosgraph/network.py", line 362, in read_ros_handshake_header
    d = sock.recv(buff_size)
error: [Errno 104] Connection reset by peer

[rospy.internal][INFO] 2020-02-27 12:57:13,975: topic[/led_control_topic] removing connection to http://itachi-HP-Pavilion-Laptop-15-cc1xx:35551/
[rospy.internal][INFO] 2020-02-27 12:57:17,816: topic[/led_control_topic] adding connection to [http://itachi-HP-Pavilion-Laptop-15-cc1xx:46105/], count 0
[rospy.internal][ERROR] 2020-02-27 13:00:18,376: Unable to initiate TCP/IP socket to itachi-HP-Pavilion-Laptop-15-cc1xx:46023 (http://itachi-HP-Pavilion-Laptop-15-cc1xx:46105/): Traceback (most recent call last):
  File "/opt/ros/kinetic/lib/python2.7/dist-packages/rospy/impl/tcpros_base.py", line 557, in connect
    self.read_header()
  File "/opt/ros/kinetic/lib/python2.7/dist-packages/rospy/impl/tcpros_base.py", line 650, in read_header
    self._validate_header(read_ros_handshake_header(sock, self.read_buff, self.protocol.buff_size))
  File "/opt/ros/kinetic/lib/python2.7/dist-packages/rospy/impl/tcpros_base.py", line 593, in _validate_header
    raise TransportInitError("remote error reported: %s"%header['error'])
TransportInitError: remote error reported: node shutting down

[rospy.internal][WARNING] 2020-02-27 13:00:19,378: Unknown error initiating TCP/IP socket to itachi-HP-Pavilion-Laptop-15-cc1xx:46023 (http://itachi-HP-Pavilion-Laptop-15-cc1xx:46105/): Traceback (most recent call last):
  File "/opt/ros/kinetic/lib/python2.7/dist-packages/rospy/impl/tcpros_base.py", line 555, in connect
    self.socket.connect((dest_addr, dest_port))
  File "/usr/lib/python2.7/socket.py", line 228, in meth
    return getattr(self._sock,name)(*args)
error: [Errno 111] Connection refused

[rospy.internal][INFO] 2020-02-27 13:00:19,378: topic[/led_control_topic] removing connection to http://itachi-HP-Pavilion-Laptop-15-cc1xx:46105/
[rospy.internal][INFO] 2020-02-27 13:02:03,501: topic[/led_control_topic] adding connection to [http://itachi-HP-Pavilion-Laptop-15-cc1xx:45187/], count 0
[rospy.internal][ERROR] 2020-02-27 13:02:30,774: Unable to initiate TCP/IP socket to itachi-HP-Pavilion-Laptop-15-cc1xx:39995 (http://itachi-HP-Pavilion-Laptop-15-cc1xx:45187/): Traceback (most recent call last):
  File "/opt/ros/kinetic/lib/python2.7/dist-packages/rospy/impl/tcpros_base.py", line 557, in connect
    self.read_header()
  File "/opt/ros/kinetic/lib/python2.7/dist-packages/rospy/impl/tcpros_base.py", line 650, in read_header
    self._validate_header(read_ros_handshake_header(sock, self.read_buff, self.protocol.buff_size))
  File "/opt/ros/kinetic/lib/python2.7/dist-packages/rospy/impl/tcpros_base.py", line 593, in _validate_header
    raise TransportInitError("remote error reported: %s"%header['error'])
TransportInitError: remote error reported: node shutting down

[rospy.internal][WARNING] 2020-02-27 13:02:31,776: Unknown error initiating TCP/IP socket to itachi-HP-Pavilion-Laptop-15-cc1xx:39995 (http://itachi-HP-Pavilion-Laptop-15-cc1xx:45187/): Traceback (most recent call last):
  File "/opt/ros/kinetic/lib/python2.7/dist-packages/rospy/impl/tcpros_base.py", line 555, in connect
    self.socket.connect((dest_addr, dest_port))
  File "/usr/lib/python2.7/socket.py", line 228, in meth
    return getattr(self._sock,name)(*args)
error: [Errno 111] Connection refused

[rospy.internal][INFO] 2020-02-27 13:02:31,776: topic[/led_control_topic] removing connection to http://itachi-HP-Pavilion-Laptop-15-cc1xx:45187/
[rospy.internal][INFO] 2020-02-27 13:02:55,142: topic[/led_control_topic] adding connection to [http://itachi-HP-Pavilion-Laptop-15-cc1xx:39491/], count 0
[rospy.internal][WARNING] 2020-02-27 13:03:30,618: Unknown error initiating TCP/IP socket to itachi-HP-Pavilion-Laptop-15-cc1xx:39277 (http://itachi-HP-Pavilion-Laptop-15-cc1xx:39491/): Traceback (most recent call last):
  File "/opt/ros/kinetic/lib/python2.7/dist-packages/rospy/impl/tcpros_base.py", line 557, in connect
    self.read_header()
  File "/opt/ros/kinetic/lib/python2.7/dist-packages/rospy/impl/tcpros_base.py", line 650, in read_header
    self._validate_header(read_ros_handshake_header(sock, self.read_buff, self.protocol.buff_size))
  File "/opt/ros/kinetic/lib/python2.7/dist-packages/rosgraph/network.py", line 362, in read_ros_handshake_header
    d = sock.recv(buff_size)
error: [Errno 104] Connection reset by peer

[rospy.internal][INFO] 2020-02-27 13:03:30,618: topic[/led_control_topic] removing connection to http://itachi-HP-Pavilion-Laptop-15-cc1xx:39491/
[rospy.internal][INFO] 2020-02-27 13:04:57,220: topic[/led_control_topic] adding connection to [http://itachi-HP-Pavilion-Laptop-15-cc1xx:41881/], count 0
[rospy.internal][ERROR] 2020-02-27 13:07:57,790: Unable to initiate TCP/IP socket to itachi-HP-Pavilion-Laptop-15-cc1xx:37303 (http://itachi-HP-Pavilion-Laptop-15-cc1xx:41881/): Traceback (most recent call last):
  File "/opt/ros/kinetic/lib/python2.7/dist-packages/rospy/impl/tcpros_base.py", line 557, in connect
    self.read_header()
  File "/opt/ros/kinetic/lib/python2.7/dist-packages/rospy/impl/tcpros_base.py", line 650, in read_header
    self._validate_header(read_ros_handshake_header(sock, self.read_buff, self.protocol.buff_size))
  File "/opt/ros/kinetic/lib/python2.7/dist-packages/rospy/impl/tcpros_base.py", line 593, in _validate_header
    raise TransportInitError("remote error reported: %s"%header['error'])
TransportInitError: remote error reported: node shutting down

[rospy.internal][WARNING] 2020-02-27 13:07:58,791: Unknown error initiating TCP/IP socket to itachi-HP-Pavilion-Laptop-15-cc1xx:37303 (http://itachi-HP-Pavilion-Laptop-15-cc1xx:41881/): Traceback (most recent call last):
  File "/opt/ros/kinetic/lib/python2.7/dist-packages/rospy/impl/tcpros_base.py", line 555, in connect
    self.socket.connect((dest_addr, dest_port))
  File "/usr/lib/python2.7/socket.py", line 228, in meth
    return getattr(self._sock,name)(*args)
error: [Errno 111] Connection refused

[rospy.internal][INFO] 2020-02-27 13:07:58,792: topic[/led_control_topic] removing connection to http://itachi-HP-Pavilion-Laptop-15-cc1xx:41881/
[rospy.core][INFO] 2020-02-27 13:23:35,078: signal_shutdown [atexit]
[rospy.internal][INFO] 2020-02-27 13:23:35,082: topic[/rosout] removing connection to /rosout
[rospy.impl.masterslave][INFO] 2020-02-27 13:23:35,082: atexit
