[rospy.client][INFO] 2020-02-28 20:30:42,659: init_node, name[/serial_node], pid[8510]
[xmlrpc][INFO] 2020-02-28 20:30:42,659: XML-RPC server binding to 0.0.0.0:0
[xmlrpc][INFO] 2020-02-28 20:30:42,660: Started XML-RPC server [http://itachi-HP-Pavilion-Laptop-15-cc1xx:44285/]
[rospy.init][INFO] 2020-02-28 20:30:42,661: ROS Slave URI: [http://itachi-HP-Pavilion-Laptop-15-cc1xx:44285/]
[rospy.impl.masterslave][INFO] 2020-02-28 20:30:42,662: _ready: http://itachi-HP-Pavilion-Laptop-15-cc1xx:44285/
[rospy.registration][INFO] 2020-02-28 20:30:42,663: Registering with master node http://localhost:11311
[xmlrpc][INFO] 2020-02-28 20:30:42,663: xml rpc node: starting XML-RPC server
[rospy.init][INFO] 2020-02-28 20:30:42,763: registered with master
[rospy.rosout][INFO] 2020-02-28 20:30:42,763: initializing /rosout core topic
[rospy.rosout][INFO] 2020-02-28 20:30:42,767: connected to core topic /rosout
[rospy.simtime][INFO] 2020-02-28 20:30:42,768: /use_sim_time is not set, will not subscribe to simulated time [/clock] topic
[rosout][INFO] 2020-02-28 20:30:42,773: ROS Serial Python Node
[rosout][INFO] 2020-02-28 20:30:42,782: Connecting to /dev/ttyUSB0 at 115200 baud
[rospy.internal][INFO] 2020-02-28 20:30:42,976: topic[/rosout] adding connection to [/rosout], count 0
[rosout][INFO] 2020-02-28 20:30:44,901: Note: subscribe buffer size is 320 bytes
[rosout][INFO] 2020-02-28 20:30:44,902: Setup subscriber on led_control_topic [std_msgs/Int8]
[rospy.internal][INFO] 2020-02-28 20:30:46,907: topic[/led_control_topic] adding connection to [http://itachi-HP-Pavilion-Laptop-15-cc1xx:45777/], count 0
[rospy.internal][WARNING] 2020-02-28 20:30:56,475: Unknown error initiating TCP/IP socket to itachi-HP-Pavilion-Laptop-15-cc1xx:46521 (http://itachi-HP-Pavilion-Laptop-15-cc1xx:45777/): Traceback (most recent call last):
  File "/opt/ros/kinetic/lib/python2.7/dist-packages/rospy/impl/tcpros_base.py", line 557, in connect
    self.read_header()
  File "/opt/ros/kinetic/lib/python2.7/dist-packages/rospy/impl/tcpros_base.py", line 650, in read_header
    self._validate_header(read_ros_handshake_header(sock, self.read_buff, self.protocol.buff_size))
  File "/opt/ros/kinetic/lib/python2.7/dist-packages/rosgraph/network.py", line 364, in read_ros_handshake_header
    raise ROSHandshakeException("connection from sender terminated before handshake header received. %s bytes were received. Please check sender for additional details."%b.tell())
ROSHandshakeException: connection from sender terminated before handshake header received. 0 bytes were received. Please check sender for additional details.

[rospy.internal][INFO] 2020-02-28 20:30:56,476: topic[/led_control_topic] removing connection to http://itachi-HP-Pavilion-Laptop-15-cc1xx:45777/
[rospy.internal][INFO] 2020-02-28 20:31:09,389: topic[/led_control_topic] adding connection to [http://itachi-HP-Pavilion-Laptop-15-cc1xx:38255/], count 0
[rospy.internal][ERROR] 2020-02-28 20:34:13,130: Unable to initiate TCP/IP socket to itachi-HP-Pavilion-Laptop-15-cc1xx:45907 (http://itachi-HP-Pavilion-Laptop-15-cc1xx:38255/): Traceback (most recent call last):
  File "/opt/ros/kinetic/lib/python2.7/dist-packages/rospy/impl/tcpros_base.py", line 557, in connect
    self.read_header()
  File "/opt/ros/kinetic/lib/python2.7/dist-packages/rospy/impl/tcpros_base.py", line 650, in read_header
    self._validate_header(read_ros_handshake_header(sock, self.read_buff, self.protocol.buff_size))
  File "/opt/ros/kinetic/lib/python2.7/dist-packages/rospy/impl/tcpros_base.py", line 593, in _validate_header
    raise TransportInitError("remote error reported: %s"%header['error'])
TransportInitError: remote error reported: node shutting down

[rospy.internal][WARNING] 2020-02-28 20:34:14,132: Unknown error initiating TCP/IP socket to itachi-HP-Pavilion-Laptop-15-cc1xx:45907 (http://itachi-HP-Pavilion-Laptop-15-cc1xx:38255/): Traceback (most recent call last):
  File "/opt/ros/kinetic/lib/python2.7/dist-packages/rospy/impl/tcpros_base.py", line 555, in connect
    self.socket.connect((dest_addr, dest_port))
  File "/usr/lib/python2.7/socket.py", line 228, in meth
    return getattr(self._sock,name)(*args)
error: [Errno 111] Connection refused

[rospy.internal][INFO] 2020-02-28 20:34:14,132: topic[/led_control_topic] removing connection to http://itachi-HP-Pavilion-Laptop-15-cc1xx:38255/
[rospy.internal][INFO] 2020-02-28 20:35:59,545: topic[/led_control_topic] adding connection to [http://itachi-HP-Pavilion-Laptop-15-cc1xx:34309/], count 0
[rospy.core][INFO] 2020-02-28 20:36:08,942: signal_shutdown [atexit]
[rospy.internal][INFO] 2020-02-28 20:36:08,945: topic[/rosout] removing connection to /rosout
[rospy.internal][INFO] 2020-02-28 20:36:08,945: topic[/led_control_topic] removing connection to http://itachi-HP-Pavilion-Laptop-15-cc1xx:34309/
[rospy.internal][WARNING] 2020-02-28 20:36:08,945: Unknown error initiating TCP/IP socket to itachi-HP-Pavilion-Laptop-15-cc1xx:43587 (http://itachi-HP-Pavilion-Laptop-15-cc1xx:34309/): Traceback (most recent call last):
  File "/opt/ros/kinetic/lib/python2.7/dist-packages/rospy/impl/tcpros_base.py", line 557, in connect
    self.read_header()
  File "/opt/ros/kinetic/lib/python2.7/dist-packages/rospy/impl/tcpros_base.py", line 650, in read_header
    self._validate_header(read_ros_handshake_header(sock, self.read_buff, self.protocol.buff_size))
AttributeError: 'NoneType' object has no attribute 'buff_size'

[rospy.topics][ERROR] 2020-02-28 20:36:08,946: Traceback (most recent call last):
  File "/opt/ros/kinetic/lib/python2.7/dist-packages/rospy/topics.py", line 326, in close
    c.close()
  File "/opt/ros/kinetic/lib/python2.7/dist-packages/rospy/impl/tcpros_base.py", line 838, in close
    self.socket.close()
AttributeError: 'NoneType' object has no attribute 'close'

[rospy.impl.masterslave][INFO] 2020-02-28 20:36:08,946: atexit
