[rospy.client][INFO] 2020-02-26 17:25:47,662: init_node, name[/serial_node], pid[26696]
[xmlrpc][INFO] 2020-02-26 17:25:47,662: XML-RPC server binding to 0.0.0.0:0
[xmlrpc][INFO] 2020-02-26 17:25:47,663: Started XML-RPC server [http://itachi-HP-Pavilion-Laptop-15-cc1xx:39969/]
[rospy.init][INFO] 2020-02-26 17:25:47,663: ROS Slave URI: [http://itachi-HP-Pavilion-Laptop-15-cc1xx:39969/]
[rospy.impl.masterslave][INFO] 2020-02-26 17:25:47,663: _ready: http://itachi-HP-Pavilion-Laptop-15-cc1xx:39969/
[rospy.registration][INFO] 2020-02-26 17:25:47,664: Registering with master node http://localhost:11311
[xmlrpc][INFO] 2020-02-26 17:25:47,664: xml rpc node: starting XML-RPC server
[rospy.init][INFO] 2020-02-26 17:25:47,764: registered with master
[rospy.rosout][INFO] 2020-02-26 17:25:47,764: initializing /rosout core topic
[rospy.rosout][INFO] 2020-02-26 17:25:47,766: connected to core topic /rosout
[rospy.simtime][INFO] 2020-02-26 17:25:47,767: /use_sim_time is not set, will not subscribe to simulated time [/clock] topic
[rosout][INFO] 2020-02-26 17:25:47,771: ROS Serial Python Node
[rosout][INFO] 2020-02-26 17:25:47,776: Connecting to /dev/ttyUSB0 at 115200 baud
[rospy.internal][INFO] 2020-02-26 17:25:48,005: topic[/rosout] adding connection to [/rosout], count 0
[rosout][INFO] 2020-02-26 17:25:49,896: Note: subscribe buffer size is 320 bytes
[rosout][INFO] 2020-02-26 17:25:49,896: Setup subscriber on led_control_topic [std_msgs/Int8]
[rospy.internal][INFO] 2020-02-26 17:26:02,937: topic[/led_control_topic] adding connection to [http://itachi-HP-Pavilion-Laptop-15-cc1xx:40737/], count 0
[rospy.internal][ERROR] 2020-02-26 17:26:50,397: Unable to initiate TCP/IP socket to itachi-HP-Pavilion-Laptop-15-cc1xx:39527 (http://itachi-HP-Pavilion-Laptop-15-cc1xx:40737/): Traceback (most recent call last):
  File "/opt/ros/kinetic/lib/python2.7/dist-packages/rospy/impl/tcpros_base.py", line 557, in connect
    self.read_header()
  File "/opt/ros/kinetic/lib/python2.7/dist-packages/rospy/impl/tcpros_base.py", line 650, in read_header
    self._validate_header(read_ros_handshake_header(sock, self.read_buff, self.protocol.buff_size))
  File "/opt/ros/kinetic/lib/python2.7/dist-packages/rospy/impl/tcpros_base.py", line 593, in _validate_header
    raise TransportInitError("remote error reported: %s"%header['error'])
TransportInitError: remote error reported: node shutting down

[rospy.internal][WARNING] 2020-02-26 17:26:51,406: Unknown error initiating TCP/IP socket to itachi-HP-Pavilion-Laptop-15-cc1xx:39527 (http://itachi-HP-Pavilion-Laptop-15-cc1xx:40737/): Traceback (most recent call last):
  File "/opt/ros/kinetic/lib/python2.7/dist-packages/rospy/impl/tcpros_base.py", line 557, in connect
    self.read_header()
  File "/opt/ros/kinetic/lib/python2.7/dist-packages/rospy/impl/tcpros_base.py", line 650, in read_header
    self._validate_header(read_ros_handshake_header(sock, self.read_buff, self.protocol.buff_size))
  File "/opt/ros/kinetic/lib/python2.7/dist-packages/rosgraph/network.py", line 362, in read_ros_handshake_header
    d = sock.recv(buff_size)
error: [Errno 104] Connection reset by peer

[rospy.internal][INFO] 2020-02-26 17:26:51,406: topic[/led_control_topic] removing connection to http://itachi-HP-Pavilion-Laptop-15-cc1xx:40737/
[rospy.internal][INFO] 2020-02-26 17:27:47,145: topic[/led_control_topic] adding connection to [http://itachi-HP-Pavilion-Laptop-15-cc1xx:37829/], count 0
[rospy.internal][ERROR] 2020-02-26 17:29:22,771: Unable to initiate TCP/IP socket to itachi-HP-Pavilion-Laptop-15-cc1xx:43283 (http://itachi-HP-Pavilion-Laptop-15-cc1xx:37829/): Traceback (most recent call last):
  File "/opt/ros/kinetic/lib/python2.7/dist-packages/rospy/impl/tcpros_base.py", line 557, in connect
    self.read_header()
  File "/opt/ros/kinetic/lib/python2.7/dist-packages/rospy/impl/tcpros_base.py", line 650, in read_header
    self._validate_header(read_ros_handshake_header(sock, self.read_buff, self.protocol.buff_size))
  File "/opt/ros/kinetic/lib/python2.7/dist-packages/rospy/impl/tcpros_base.py", line 593, in _validate_header
    raise TransportInitError("remote error reported: %s"%header['error'])
TransportInitError: remote error reported: node shutting down

[rospy.internal][WARNING] 2020-02-26 17:29:23,773: Unknown error initiating TCP/IP socket to itachi-HP-Pavilion-Laptop-15-cc1xx:43283 (http://itachi-HP-Pavilion-Laptop-15-cc1xx:37829/): Traceback (most recent call last):
  File "/opt/ros/kinetic/lib/python2.7/dist-packages/rospy/impl/tcpros_base.py", line 555, in connect
    self.socket.connect((dest_addr, dest_port))
  File "/usr/lib/python2.7/socket.py", line 228, in meth
    return getattr(self._sock,name)(*args)
error: [Errno 111] Connection refused

[rospy.internal][INFO] 2020-02-26 17:29:23,773: topic[/led_control_topic] removing connection to http://itachi-HP-Pavilion-Laptop-15-cc1xx:37829/
[rospy.internal][INFO] 2020-02-26 17:29:28,863: topic[/led_control_topic] adding connection to [http://itachi-HP-Pavilion-Laptop-15-cc1xx:36953/], count 0
[rospy.internal][ERROR] 2020-02-26 17:32:29,028: Unable to initiate TCP/IP socket to itachi-HP-Pavilion-Laptop-15-cc1xx:41495 (http://itachi-HP-Pavilion-Laptop-15-cc1xx:36953/): Traceback (most recent call last):
  File "/opt/ros/kinetic/lib/python2.7/dist-packages/rospy/impl/tcpros_base.py", line 557, in connect
    self.read_header()
  File "/opt/ros/kinetic/lib/python2.7/dist-packages/rospy/impl/tcpros_base.py", line 650, in read_header
    self._validate_header(read_ros_handshake_header(sock, self.read_buff, self.protocol.buff_size))
  File "/opt/ros/kinetic/lib/python2.7/dist-packages/rospy/impl/tcpros_base.py", line 593, in _validate_header
    raise TransportInitError("remote error reported: %s"%header['error'])
TransportInitError: remote error reported: node shutting down

[rospy.internal][WARNING] 2020-02-26 17:32:30,029: Unknown error initiating TCP/IP socket to itachi-HP-Pavilion-Laptop-15-cc1xx:41495 (http://itachi-HP-Pavilion-Laptop-15-cc1xx:36953/): Traceback (most recent call last):
  File "/opt/ros/kinetic/lib/python2.7/dist-packages/rospy/impl/tcpros_base.py", line 555, in connect
    self.socket.connect((dest_addr, dest_port))
  File "/usr/lib/python2.7/socket.py", line 228, in meth
    return getattr(self._sock,name)(*args)
error: [Errno 111] Connection refused

[rospy.internal][INFO] 2020-02-26 17:32:30,030: topic[/led_control_topic] removing connection to http://itachi-HP-Pavilion-Laptop-15-cc1xx:36953/
[rospy.internal][INFO] 2020-02-26 17:38:19,344: topic[/led_control_topic] adding connection to [http://itachi-HP-Pavilion-Laptop-15-cc1xx:38551/], count 0
[rospy.internal][ERROR] 2020-02-26 17:39:11,609: Unable to initiate TCP/IP socket to itachi-HP-Pavilion-Laptop-15-cc1xx:35859 (http://itachi-HP-Pavilion-Laptop-15-cc1xx:38551/): Traceback (most recent call last):
  File "/opt/ros/kinetic/lib/python2.7/dist-packages/rospy/impl/tcpros_base.py", line 557, in connect
    self.read_header()
  File "/opt/ros/kinetic/lib/python2.7/dist-packages/rospy/impl/tcpros_base.py", line 650, in read_header
    self._validate_header(read_ros_handshake_header(sock, self.read_buff, self.protocol.buff_size))
  File "/opt/ros/kinetic/lib/python2.7/dist-packages/rospy/impl/tcpros_base.py", line 593, in _validate_header
    raise TransportInitError("remote error reported: %s"%header['error'])
TransportInitError: remote error reported: node shutting down

[rospy.internal][WARNING] 2020-02-26 17:39:12,610: Unknown error initiating TCP/IP socket to itachi-HP-Pavilion-Laptop-15-cc1xx:35859 (http://itachi-HP-Pavilion-Laptop-15-cc1xx:38551/): Traceback (most recent call last):
  File "/opt/ros/kinetic/lib/python2.7/dist-packages/rospy/impl/tcpros_base.py", line 555, in connect
    self.socket.connect((dest_addr, dest_port))
  File "/usr/lib/python2.7/socket.py", line 228, in meth
    return getattr(self._sock,name)(*args)
error: [Errno 111] Connection refused

[rospy.internal][INFO] 2020-02-26 17:39:12,611: topic[/led_control_topic] removing connection to http://itachi-HP-Pavilion-Laptop-15-cc1xx:38551/
[rospy.internal][INFO] 2020-02-26 17:52:44,783: topic[/led_control_topic] adding connection to [http://itachi-HP-Pavilion-Laptop-15-cc1xx:46719/], count 0
[rospy.internal][ERROR] 2020-02-26 17:53:26,952: Unable to initiate TCP/IP socket to itachi-HP-Pavilion-Laptop-15-cc1xx:34087 (http://itachi-HP-Pavilion-Laptop-15-cc1xx:46719/): Traceback (most recent call last):
  File "/opt/ros/kinetic/lib/python2.7/dist-packages/rospy/impl/tcpros_base.py", line 557, in connect
    self.read_header()
  File "/opt/ros/kinetic/lib/python2.7/dist-packages/rospy/impl/tcpros_base.py", line 650, in read_header
    self._validate_header(read_ros_handshake_header(sock, self.read_buff, self.protocol.buff_size))
  File "/opt/ros/kinetic/lib/python2.7/dist-packages/rospy/impl/tcpros_base.py", line 593, in _validate_header
    raise TransportInitError("remote error reported: %s"%header['error'])
TransportInitError: remote error reported: node shutting down

[rospy.internal][WARNING] 2020-02-26 17:53:27,953: Unknown error initiating TCP/IP socket to itachi-HP-Pavilion-Laptop-15-cc1xx:34087 (http://itachi-HP-Pavilion-Laptop-15-cc1xx:46719/): Traceback (most recent call last):
  File "/opt/ros/kinetic/lib/python2.7/dist-packages/rospy/impl/tcpros_base.py", line 555, in connect
    self.socket.connect((dest_addr, dest_port))
  File "/usr/lib/python2.7/socket.py", line 228, in meth
    return getattr(self._sock,name)(*args)
error: [Errno 111] Connection refused

[rospy.internal][INFO] 2020-02-26 17:53:27,953: topic[/led_control_topic] removing connection to http://itachi-HP-Pavilion-Laptop-15-cc1xx:46719/
[rospy.internal][INFO] 2020-02-26 17:53:30,627: topic[/led_control_topic] adding connection to [http://itachi-HP-Pavilion-Laptop-15-cc1xx:43991/], count 0
[rospy.internal][ERROR] 2020-02-26 17:56:30,817: Unable to initiate TCP/IP socket to itachi-HP-Pavilion-Laptop-15-cc1xx:46811 (http://itachi-HP-Pavilion-Laptop-15-cc1xx:43991/): Traceback (most recent call last):
  File "/opt/ros/kinetic/lib/python2.7/dist-packages/rospy/impl/tcpros_base.py", line 557, in connect
    self.read_header()
  File "/opt/ros/kinetic/lib/python2.7/dist-packages/rospy/impl/tcpros_base.py", line 650, in read_header
    self._validate_header(read_ros_handshake_header(sock, self.read_buff, self.protocol.buff_size))
  File "/opt/ros/kinetic/lib/python2.7/dist-packages/rospy/impl/tcpros_base.py", line 593, in _validate_header
    raise TransportInitError("remote error reported: %s"%header['error'])
TransportInitError: remote error reported: node shutting down

[rospy.internal][WARNING] 2020-02-26 17:56:31,818: Unknown error initiating TCP/IP socket to itachi-HP-Pavilion-Laptop-15-cc1xx:46811 (http://itachi-HP-Pavilion-Laptop-15-cc1xx:43991/): Traceback (most recent call last):
  File "/opt/ros/kinetic/lib/python2.7/dist-packages/rospy/impl/tcpros_base.py", line 555, in connect
    self.socket.connect((dest_addr, dest_port))
  File "/usr/lib/python2.7/socket.py", line 228, in meth
    return getattr(self._sock,name)(*args)
error: [Errno 111] Connection refused

[rospy.internal][INFO] 2020-02-26 17:56:31,818: topic[/led_control_topic] removing connection to http://itachi-HP-Pavilion-Laptop-15-cc1xx:43991/
[rospy.internal][INFO] 2020-02-26 17:58:21,629: topic[/led_control_topic] adding connection to [http://itachi-HP-Pavilion-Laptop-15-cc1xx:37909/], count 0
[rospy.internal][ERROR] 2020-02-26 17:59:01,785: Unable to initiate TCP/IP socket to itachi-HP-Pavilion-Laptop-15-cc1xx:42119 (http://itachi-HP-Pavilion-Laptop-15-cc1xx:37909/): Traceback (most recent call last):
  File "/opt/ros/kinetic/lib/python2.7/dist-packages/rospy/impl/tcpros_base.py", line 557, in connect
    self.read_header()
  File "/opt/ros/kinetic/lib/python2.7/dist-packages/rospy/impl/tcpros_base.py", line 650, in read_header
    self._validate_header(read_ros_handshake_header(sock, self.read_buff, self.protocol.buff_size))
  File "/opt/ros/kinetic/lib/python2.7/dist-packages/rospy/impl/tcpros_base.py", line 593, in _validate_header
    raise TransportInitError("remote error reported: %s"%header['error'])
TransportInitError: remote error reported: node shutting down

[rospy.internal][WARNING] 2020-02-26 17:59:02,786: Unknown error initiating TCP/IP socket to itachi-HP-Pavilion-Laptop-15-cc1xx:42119 (http://itachi-HP-Pavilion-Laptop-15-cc1xx:37909/): Traceback (most recent call last):
  File "/opt/ros/kinetic/lib/python2.7/dist-packages/rospy/impl/tcpros_base.py", line 555, in connect
    self.socket.connect((dest_addr, dest_port))
  File "/usr/lib/python2.7/socket.py", line 228, in meth
    return getattr(self._sock,name)(*args)
error: [Errno 111] Connection refused

[rospy.internal][INFO] 2020-02-26 17:59:02,786: topic[/led_control_topic] removing connection to http://itachi-HP-Pavilion-Laptop-15-cc1xx:37909/
[rospy.internal][INFO] 2020-02-26 18:01:24,524: topic[/led_control_topic] adding connection to [http://itachi-HP-Pavilion-Laptop-15-cc1xx:36973/], count 0
[rospy.internal][ERROR] 2020-02-26 18:01:50,822: Unable to initiate TCP/IP socket to itachi-HP-Pavilion-Laptop-15-cc1xx:33801 (http://itachi-HP-Pavilion-Laptop-15-cc1xx:36973/): Traceback (most recent call last):
  File "/opt/ros/kinetic/lib/python2.7/dist-packages/rospy/impl/tcpros_base.py", line 557, in connect
    self.read_header()
  File "/opt/ros/kinetic/lib/python2.7/dist-packages/rospy/impl/tcpros_base.py", line 650, in read_header
    self._validate_header(read_ros_handshake_header(sock, self.read_buff, self.protocol.buff_size))
  File "/opt/ros/kinetic/lib/python2.7/dist-packages/rospy/impl/tcpros_base.py", line 593, in _validate_header
    raise TransportInitError("remote error reported: %s"%header['error'])
TransportInitError: remote error reported: node shutting down

[rospy.internal][WARNING] 2020-02-26 18:01:51,824: Unknown error initiating TCP/IP socket to itachi-HP-Pavilion-Laptop-15-cc1xx:33801 (http://itachi-HP-Pavilion-Laptop-15-cc1xx:36973/): Traceback (most recent call last):
  File "/opt/ros/kinetic/lib/python2.7/dist-packages/rospy/impl/tcpros_base.py", line 555, in connect
    self.socket.connect((dest_addr, dest_port))
  File "/usr/lib/python2.7/socket.py", line 228, in meth
    return getattr(self._sock,name)(*args)
error: [Errno 111] Connection refused

[rospy.internal][INFO] 2020-02-26 18:01:51,824: topic[/led_control_topic] removing connection to http://itachi-HP-Pavilion-Laptop-15-cc1xx:36973/
[rospy.internal][INFO] 2020-02-26 18:01:53,699: topic[/led_control_topic] adding connection to [http://itachi-HP-Pavilion-Laptop-15-cc1xx:41355/], count 0
[rospy.internal][ERROR] 2020-02-26 18:02:30,912: Unable to initiate TCP/IP socket to itachi-HP-Pavilion-Laptop-15-cc1xx:46771 (http://itachi-HP-Pavilion-Laptop-15-cc1xx:41355/): Traceback (most recent call last):
  File "/opt/ros/kinetic/lib/python2.7/dist-packages/rospy/impl/tcpros_base.py", line 557, in connect
    self.read_header()
  File "/opt/ros/kinetic/lib/python2.7/dist-packages/rospy/impl/tcpros_base.py", line 650, in read_header
    self._validate_header(read_ros_handshake_header(sock, self.read_buff, self.protocol.buff_size))
  File "/opt/ros/kinetic/lib/python2.7/dist-packages/rospy/impl/tcpros_base.py", line 593, in _validate_header
    raise TransportInitError("remote error reported: %s"%header['error'])
TransportInitError: remote error reported: node shutting down

[rospy.internal][WARNING] 2020-02-26 18:02:31,914: Unknown error initiating TCP/IP socket to itachi-HP-Pavilion-Laptop-15-cc1xx:46771 (http://itachi-HP-Pavilion-Laptop-15-cc1xx:41355/): Traceback (most recent call last):
  File "/opt/ros/kinetic/lib/python2.7/dist-packages/rospy/impl/tcpros_base.py", line 555, in connect
    self.socket.connect((dest_addr, dest_port))
  File "/usr/lib/python2.7/socket.py", line 228, in meth
    return getattr(self._sock,name)(*args)
error: [Errno 111] Connection refused

[rospy.internal][INFO] 2020-02-26 18:02:31,914: topic[/led_control_topic] removing connection to http://itachi-HP-Pavilion-Laptop-15-cc1xx:41355/
[rospy.internal][INFO] 2020-02-26 18:06:23,229: topic[/led_control_topic] adding connection to [http://itachi-HP-Pavilion-Laptop-15-cc1xx:44253/], count 0
[rospy.internal][ERROR] 2020-02-26 18:06:43,473: Unable to initiate TCP/IP socket to itachi-HP-Pavilion-Laptop-15-cc1xx:46465 (http://itachi-HP-Pavilion-Laptop-15-cc1xx:44253/): Traceback (most recent call last):
  File "/opt/ros/kinetic/lib/python2.7/dist-packages/rospy/impl/tcpros_base.py", line 557, in connect
    self.read_header()
  File "/opt/ros/kinetic/lib/python2.7/dist-packages/rospy/impl/tcpros_base.py", line 650, in read_header
    self._validate_header(read_ros_handshake_header(sock, self.read_buff, self.protocol.buff_size))
  File "/opt/ros/kinetic/lib/python2.7/dist-packages/rospy/impl/tcpros_base.py", line 593, in _validate_header
    raise TransportInitError("remote error reported: %s"%header['error'])
TransportInitError: remote error reported: node shutting down

[rospy.internal][WARNING] 2020-02-26 18:06:44,474: Unknown error initiating TCP/IP socket to itachi-HP-Pavilion-Laptop-15-cc1xx:46465 (http://itachi-HP-Pavilion-Laptop-15-cc1xx:44253/): Traceback (most recent call last):
  File "/opt/ros/kinetic/lib/python2.7/dist-packages/rospy/impl/tcpros_base.py", line 555, in connect
    self.socket.connect((dest_addr, dest_port))
  File "/usr/lib/python2.7/socket.py", line 228, in meth
    return getattr(self._sock,name)(*args)
error: [Errno 111] Connection refused

[rospy.internal][INFO] 2020-02-26 18:06:44,474: topic[/led_control_topic] removing connection to http://itachi-HP-Pavilion-Laptop-15-cc1xx:44253/
[rospy.internal][INFO] 2020-02-26 18:06:49,706: topic[/led_control_topic] adding connection to [http://itachi-HP-Pavilion-Laptop-15-cc1xx:43415/], count 0
[rospy.internal][ERROR] 2020-02-26 18:07:29,378: Unable to initiate TCP/IP socket to itachi-HP-Pavilion-Laptop-15-cc1xx:37957 (http://itachi-HP-Pavilion-Laptop-15-cc1xx:43415/): Traceback (most recent call last):
  File "/opt/ros/kinetic/lib/python2.7/dist-packages/rospy/impl/tcpros_base.py", line 557, in connect
    self.read_header()
  File "/opt/ros/kinetic/lib/python2.7/dist-packages/rospy/impl/tcpros_base.py", line 650, in read_header
    self._validate_header(read_ros_handshake_header(sock, self.read_buff, self.protocol.buff_size))
  File "/opt/ros/kinetic/lib/python2.7/dist-packages/rospy/impl/tcpros_base.py", line 593, in _validate_header
    raise TransportInitError("remote error reported: %s"%header['error'])
TransportInitError: remote error reported: node shutting down

[rospy.internal][WARNING] 2020-02-26 18:07:30,379: Unknown error initiating TCP/IP socket to itachi-HP-Pavilion-Laptop-15-cc1xx:37957 (http://itachi-HP-Pavilion-Laptop-15-cc1xx:43415/): Traceback (most recent call last):
  File "/opt/ros/kinetic/lib/python2.7/dist-packages/rospy/impl/tcpros_base.py", line 555, in connect
    self.socket.connect((dest_addr, dest_port))
  File "/usr/lib/python2.7/socket.py", line 228, in meth
    return getattr(self._sock,name)(*args)
error: [Errno 111] Connection refused

[rospy.internal][INFO] 2020-02-26 18:07:30,379: topic[/led_control_topic] removing connection to http://itachi-HP-Pavilion-Laptop-15-cc1xx:43415/
[rosout][INFO] 2020-02-26 18:07:50,339: Send tx stop request
[rospy.core][INFO] 2020-02-26 18:07:50,339: signal_shutdown [atexit]
[rospy.internal][INFO] 2020-02-26 18:07:50,342: topic[/rosout] removing connection to /rosout
[rospy.impl.masterslave][INFO] 2020-02-26 18:07:50,342: atexit
