[rospy.client][INFO] 2020-02-28 18:20:13,034: init_node, name[/rostopic_8240_1582894212993], pid[8240]
[xmlrpc][INFO] 2020-02-28 18:20:13,037: XML-RPC server binding to 0.0.0.0:0
[xmlrpc][INFO] 2020-02-28 18:20:13,037: Started XML-RPC server [http://itachi-HP-Pavilion-Laptop-15-cc1xx:34599/]
[rospy.init][INFO] 2020-02-28 18:20:13,037: ROS Slave URI: [http://itachi-HP-Pavilion-Laptop-15-cc1xx:34599/]
[rospy.impl.masterslave][INFO] 2020-02-28 18:20:13,038: _ready: http://itachi-HP-Pavilion-Laptop-15-cc1xx:34599/
[xmlrpc][INFO] 2020-02-28 18:20:13,039: xml rpc node: starting XML-RPC server
[rospy.registration][INFO] 2020-02-28 18:20:13,039: Registering with master node http://localhost:11311
[rospy.init][INFO] 2020-02-28 18:20:13,138: registered with master
[rospy.rosout][INFO] 2020-02-28 18:20:13,138: initializing /rosout core topic
[rospy.rosout][INFO] 2020-02-28 18:20:13,142: connected to core topic /rosout
[rospy.simtime][INFO] 2020-02-28 18:20:13,143: /use_sim_time is not set, will not subscribe to simulated time [/clock] topic
[rospy.internal][INFO] 2020-02-28 18:20:13,390: topic[/rosout] adding connection to [/rosout], count 0
[rospy.internal][INFO] 2020-02-28 18:20:57,636: topic[/stats_sr] adding connection to [http://itachi-HP-Pavilion-Laptop-15-cc1xx:46253/], count 0
[rospy.internal][ERROR] 2020-02-28 18:23:42,205: Unable to initiate TCP/IP socket to itachi-HP-Pavilion-Laptop-15-cc1xx:39931 (http://itachi-HP-Pavilion-Laptop-15-cc1xx:46253/): Traceback (most recent call last):
  File "/opt/ros/kinetic/lib/python2.7/dist-packages/rospy/impl/tcpros_base.py", line 557, in connect
    self.read_header()
  File "/opt/ros/kinetic/lib/python2.7/dist-packages/rospy/impl/tcpros_base.py", line 650, in read_header
    self._validate_header(read_ros_handshake_header(sock, self.read_buff, self.protocol.buff_size))
  File "/opt/ros/kinetic/lib/python2.7/dist-packages/rospy/impl/tcpros_base.py", line 593, in _validate_header
    raise TransportInitError("remote error reported: %s"%header['error'])
TransportInitError: remote error reported: node shutting down

[rospy.internal][WARNING] 2020-02-28 18:23:43,206: Unknown error initiating TCP/IP socket to itachi-HP-Pavilion-Laptop-15-cc1xx:39931 (http://itachi-HP-Pavilion-Laptop-15-cc1xx:46253/): Traceback (most recent call last):
  File "/opt/ros/kinetic/lib/python2.7/dist-packages/rospy/impl/tcpros_base.py", line 555, in connect
    self.socket.connect((dest_addr, dest_port))
  File "/usr/lib/python2.7/socket.py", line 228, in meth
    return getattr(self._sock,name)(*args)
error: [Errno 111] Connection refused

[rospy.internal][INFO] 2020-02-28 18:23:43,207: topic[/stats_sr] removing connection to http://itachi-HP-Pavilion-Laptop-15-cc1xx:46253/
[rospy.core][INFO] 2020-02-28 18:23:45,641: signal_shutdown [signal-2]
[rospy.internal][INFO] 2020-02-28 18:23:45,644: topic[/rosout] removing connection to /rosout
[rospy.impl.masterslave][INFO] 2020-02-28 18:23:45,644: signal-2
[rospy.core][INFO] 2020-02-28 18:23:45,809: signal_shutdown [atexit]
