[rospy.client][INFO] 2020-02-28 16:14:29,936: init_node, name[/rostopic_16890_1582886669868], pid[16890]
[xmlrpc][INFO] 2020-02-28 16:14:29,937: XML-RPC server binding to 0.0.0.0:0
[xmlrpc][INFO] 2020-02-28 16:14:29,940: Started XML-RPC server [http://itachi-HP-Pavilion-Laptop-15-cc1xx:32943/]
[rospy.init][INFO] 2020-02-28 16:14:29,941: ROS Slave URI: [http://itachi-HP-Pavilion-Laptop-15-cc1xx:32943/]
[rospy.impl.masterslave][INFO] 2020-02-28 16:14:29,941: _ready: http://itachi-HP-Pavilion-Laptop-15-cc1xx:32943/
[rospy.registration][INFO] 2020-02-28 16:14:29,943: Registering with master node http://localhost:11311
[xmlrpc][INFO] 2020-02-28 16:14:29,944: xml rpc node: starting XML-RPC server
[rospy.init][INFO] 2020-02-28 16:14:30,042: registered with master
[rospy.rosout][INFO] 2020-02-28 16:14:30,043: initializing /rosout core topic
[rospy.rosout][INFO] 2020-02-28 16:14:30,045: connected to core topic /rosout
[rospy.simtime][INFO] 2020-02-28 16:14:30,046: /use_sim_time is not set, will not subscribe to simulated time [/clock] topic
[rospy.internal][INFO] 2020-02-28 16:14:30,333: topic[/rosout] adding connection to [/rosout], count 0
[rospy.internal][INFO] 2020-02-28 16:14:50,002: topic[/stats_sr] adding connection to [http://itachi-HP-Pavilion-Laptop-15-cc1xx:44425/], count 0
[rospy.internal][ERROR] 2020-02-28 16:14:50,630: Unable to initiate TCP/IP socket to itachi-HP-Pavilion-Laptop-15-cc1xx:33079 (http://itachi-HP-Pavilion-Laptop-15-cc1xx:44425/): Traceback (most recent call last):
  File "/opt/ros/kinetic/lib/python2.7/dist-packages/rospy/impl/tcpros_base.py", line 557, in connect
    self.read_header()
  File "/opt/ros/kinetic/lib/python2.7/dist-packages/rospy/impl/tcpros_base.py", line 650, in read_header
    self._validate_header(read_ros_handshake_header(sock, self.read_buff, self.protocol.buff_size))
  File "/opt/ros/kinetic/lib/python2.7/dist-packages/rospy/impl/tcpros_base.py", line 593, in _validate_header
    raise TransportInitError("remote error reported: %s"%header['error'])
TransportInitError: remote error reported: node shutting down

[rospy.internal][WARNING] 2020-02-28 16:14:51,632: Unknown error initiating TCP/IP socket to itachi-HP-Pavilion-Laptop-15-cc1xx:33079 (http://itachi-HP-Pavilion-Laptop-15-cc1xx:44425/): Traceback (most recent call last):
  File "/opt/ros/kinetic/lib/python2.7/dist-packages/rospy/impl/tcpros_base.py", line 555, in connect
    self.socket.connect((dest_addr, dest_port))
  File "/usr/lib/python2.7/socket.py", line 228, in meth
    return getattr(self._sock,name)(*args)
error: [Errno 111] Connection refused

[rospy.internal][INFO] 2020-02-28 16:14:51,633: topic[/stats_sr] removing connection to http://itachi-HP-Pavilion-Laptop-15-cc1xx:44425/
[rospy.internal][INFO] 2020-02-28 16:15:07,170: topic[/stats_sr] adding connection to [http://itachi-HP-Pavilion-Laptop-15-cc1xx:40365/], count 0
[rospy.internal][ERROR] 2020-02-28 16:15:12,865: Unable to initiate TCP/IP socket to itachi-HP-Pavilion-Laptop-15-cc1xx:36743 (http://itachi-HP-Pavilion-Laptop-15-cc1xx:40365/): Traceback (most recent call last):
  File "/opt/ros/kinetic/lib/python2.7/dist-packages/rospy/impl/tcpros_base.py", line 557, in connect
    self.read_header()
  File "/opt/ros/kinetic/lib/python2.7/dist-packages/rospy/impl/tcpros_base.py", line 650, in read_header
    self._validate_header(read_ros_handshake_header(sock, self.read_buff, self.protocol.buff_size))
  File "/opt/ros/kinetic/lib/python2.7/dist-packages/rospy/impl/tcpros_base.py", line 593, in _validate_header
    raise TransportInitError("remote error reported: %s"%header['error'])
TransportInitError: remote error reported: node shutting down

[rospy.internal][WARNING] 2020-02-28 16:15:13,868: Unknown error initiating TCP/IP socket to itachi-HP-Pavilion-Laptop-15-cc1xx:36743 (http://itachi-HP-Pavilion-Laptop-15-cc1xx:40365/): Traceback (most recent call last):
  File "/opt/ros/kinetic/lib/python2.7/dist-packages/rospy/impl/tcpros_base.py", line 555, in connect
    self.socket.connect((dest_addr, dest_port))
  File "/usr/lib/python2.7/socket.py", line 228, in meth
    return getattr(self._sock,name)(*args)
error: [Errno 111] Connection refused

[rospy.internal][INFO] 2020-02-28 16:15:13,868: topic[/stats_sr] removing connection to http://itachi-HP-Pavilion-Laptop-15-cc1xx:40365/
[rospy.internal][INFO] 2020-02-28 16:15:59,322: topic[/stats_sr] adding connection to [http://itachi-HP-Pavilion-Laptop-15-cc1xx:44007/], count 0
[rospy.internal][WARNING] 2020-02-28 16:19:02,546: Unknown error initiating TCP/IP socket to itachi-HP-Pavilion-Laptop-15-cc1xx:39445 (http://itachi-HP-Pavilion-Laptop-15-cc1xx:44007/): Traceback (most recent call last):
  File "/opt/ros/kinetic/lib/python2.7/dist-packages/rospy/impl/tcpros_base.py", line 557, in connect
    self.read_header()
  File "/opt/ros/kinetic/lib/python2.7/dist-packages/rospy/impl/tcpros_base.py", line 650, in read_header
    self._validate_header(read_ros_handshake_header(sock, self.read_buff, self.protocol.buff_size))
  File "/opt/ros/kinetic/lib/python2.7/dist-packages/rosgraph/network.py", line 364, in read_ros_handshake_header
    raise ROSHandshakeException("connection from sender terminated before handshake header received. %s bytes were received. Please check sender for additional details."%b.tell())
ROSHandshakeException: connection from sender terminated before handshake header received. 0 bytes were received. Please check sender for additional details.

[rospy.internal][INFO] 2020-02-28 16:19:02,547: topic[/stats_sr] removing connection to http://itachi-HP-Pavilion-Laptop-15-cc1xx:44007/
[rospy.internal][INFO] 2020-02-28 16:20:18,268: topic[/stats_sr] adding connection to [http://itachi-HP-Pavilion-Laptop-15-cc1xx:34495/], count 0
[rospy.internal][ERROR] 2020-02-28 16:20:41,499: Unable to initiate TCP/IP socket to itachi-HP-Pavilion-Laptop-15-cc1xx:34117 (http://itachi-HP-Pavilion-Laptop-15-cc1xx:34495/): Traceback (most recent call last):
  File "/opt/ros/kinetic/lib/python2.7/dist-packages/rospy/impl/tcpros_base.py", line 557, in connect
    self.read_header()
  File "/opt/ros/kinetic/lib/python2.7/dist-packages/rospy/impl/tcpros_base.py", line 650, in read_header
    self._validate_header(read_ros_handshake_header(sock, self.read_buff, self.protocol.buff_size))
  File "/opt/ros/kinetic/lib/python2.7/dist-packages/rospy/impl/tcpros_base.py", line 593, in _validate_header
    raise TransportInitError("remote error reported: %s"%header['error'])
TransportInitError: remote error reported: node shutting down

[rospy.internal][WARNING] 2020-02-28 16:20:42,500: Unknown error initiating TCP/IP socket to itachi-HP-Pavilion-Laptop-15-cc1xx:34117 (http://itachi-HP-Pavilion-Laptop-15-cc1xx:34495/): Traceback (most recent call last):
  File "/opt/ros/kinetic/lib/python2.7/dist-packages/rospy/impl/tcpros_base.py", line 555, in connect
    self.socket.connect((dest_addr, dest_port))
  File "/usr/lib/python2.7/socket.py", line 228, in meth
    return getattr(self._sock,name)(*args)
error: [Errno 111] Connection refused

[rospy.internal][INFO] 2020-02-28 16:20:42,500: topic[/stats_sr] removing connection to http://itachi-HP-Pavilion-Laptop-15-cc1xx:34495/
[rospy.internal][INFO] 2020-02-28 16:23:16,872: topic[/stats_sr] adding connection to [http://itachi-HP-Pavilion-Laptop-15-cc1xx:38317/], count 0
[rospy.internal][ERROR] 2020-02-28 16:23:24,724: Unable to initiate TCP/IP socket to itachi-HP-Pavilion-Laptop-15-cc1xx:43573 (http://itachi-HP-Pavilion-Laptop-15-cc1xx:38317/): Traceback (most recent call last):
  File "/opt/ros/kinetic/lib/python2.7/dist-packages/rospy/impl/tcpros_base.py", line 557, in connect
    self.read_header()
  File "/opt/ros/kinetic/lib/python2.7/dist-packages/rospy/impl/tcpros_base.py", line 650, in read_header
    self._validate_header(read_ros_handshake_header(sock, self.read_buff, self.protocol.buff_size))
  File "/opt/ros/kinetic/lib/python2.7/dist-packages/rospy/impl/tcpros_base.py", line 593, in _validate_header
    raise TransportInitError("remote error reported: %s"%header['error'])
TransportInitError: remote error reported: node shutting down

[rospy.internal][WARNING] 2020-02-28 16:23:25,727: Unknown error initiating TCP/IP socket to itachi-HP-Pavilion-Laptop-15-cc1xx:43573 (http://itachi-HP-Pavilion-Laptop-15-cc1xx:38317/): Traceback (most recent call last):
  File "/opt/ros/kinetic/lib/python2.7/dist-packages/rospy/impl/tcpros_base.py", line 555, in connect
    self.socket.connect((dest_addr, dest_port))
  File "/usr/lib/python2.7/socket.py", line 228, in meth
    return getattr(self._sock,name)(*args)
error: [Errno 111] Connection refused

[rospy.internal][INFO] 2020-02-28 16:23:25,727: topic[/stats_sr] removing connection to http://itachi-HP-Pavilion-Laptop-15-cc1xx:38317/
