[rospy.client][INFO] 2020-02-03 01:20:22,565: init_node, name[/rostopic_12365_1580673022516], pid[12365]
[xmlrpc][INFO] 2020-02-03 01:20:22,566: XML-RPC server binding to 0.0.0.0:0
[xmlrpc][INFO] 2020-02-03 01:20:22,566: Started XML-RPC server [http://itachi-HP-Pavilion-Laptop-15-cc1xx:39927/]
[rospy.init][INFO] 2020-02-03 01:20:22,566: ROS Slave URI: [http://itachi-HP-Pavilion-Laptop-15-cc1xx:39927/]
[rospy.impl.masterslave][INFO] 2020-02-03 01:20:22,567: _ready: http://itachi-HP-Pavilion-Laptop-15-cc1xx:39927/
[rospy.registration][INFO] 2020-02-03 01:20:22,567: Registering with master node http://localhost:11311
[xmlrpc][INFO] 2020-02-03 01:20:22,568: xml rpc node: starting XML-RPC server
[rospy.init][INFO] 2020-02-03 01:20:22,667: registered with master
[rospy.rosout][INFO] 2020-02-03 01:20:22,668: initializing /rosout core topic
[rospy.rosout][INFO] 2020-02-03 01:20:22,674: connected to core topic /rosout
[rospy.simtime][INFO] 2020-02-03 01:20:22,681: /use_sim_time is not set, will not subscribe to simulated time [/clock] topic
[rospy.internal][INFO] 2020-02-03 01:20:22,734: topic[/detection_info] adding connection to [http://itachi-HP-Pavilion-Laptop-15-cc1xx:35287/], count 0
[rospy.internal][INFO] 2020-02-03 01:20:22,895: topic[/rosout] adding connection to [/rosout], count 0
[rospy.internal][ERROR] 2020-02-03 01:21:27,343: Unable to initiate TCP/IP socket to itachi-HP-Pavilion-Laptop-15-cc1xx:41787 (http://itachi-HP-Pavilion-Laptop-15-cc1xx:35287/): Traceback (most recent call last):
  File "/opt/ros/kinetic/lib/python2.7/dist-packages/rospy/impl/tcpros_base.py", line 557, in connect
    self.read_header()
  File "/opt/ros/kinetic/lib/python2.7/dist-packages/rospy/impl/tcpros_base.py", line 650, in read_header
    self._validate_header(read_ros_handshake_header(sock, self.read_buff, self.protocol.buff_size))
  File "/opt/ros/kinetic/lib/python2.7/dist-packages/rospy/impl/tcpros_base.py", line 593, in _validate_header
    raise TransportInitError("remote error reported: %s"%header['error'])
TransportInitError: remote error reported: node shutting down

[rospy.internal][WARNING] 2020-02-03 01:21:28,345: Unknown error initiating TCP/IP socket to itachi-HP-Pavilion-Laptop-15-cc1xx:41787 (http://itachi-HP-Pavilion-Laptop-15-cc1xx:35287/): Traceback (most recent call last):
  File "/opt/ros/kinetic/lib/python2.7/dist-packages/rospy/impl/tcpros_base.py", line 555, in connect
    self.socket.connect((dest_addr, dest_port))
  File "/usr/lib/python2.7/socket.py", line 228, in meth
    return getattr(self._sock,name)(*args)
error: [Errno 111] Connection refused

[rospy.internal][INFO] 2020-02-03 01:21:28,345: topic[/detection_info] removing connection to http://itachi-HP-Pavilion-Laptop-15-cc1xx:35287/
[rospy.core][INFO] 2020-02-03 01:22:12,737: signal_shutdown [signal-2]
[rospy.internal][INFO] 2020-02-03 01:22:12,746: topic[/rosout] removing connection to /rosout
[rospy.impl.masterslave][INFO] 2020-02-03 01:22:12,747: signal-2
[rospy.core][INFO] 2020-02-03 01:22:12,880: signal_shutdown [atexit]
