[rospy.client][INFO] 2020-02-03 22:49:44,110: init_node, name[/rostopic_5265_1580750384075], pid[5265]
[xmlrpc][INFO] 2020-02-03 22:49:44,110: XML-RPC server binding to 0.0.0.0:0
[xmlrpc][INFO] 2020-02-03 22:49:44,111: Started XML-RPC server [http://itachi-HP-Pavilion-Laptop-15-cc1xx:44373/]
[rospy.init][INFO] 2020-02-03 22:49:44,111: ROS Slave URI: [http://itachi-HP-Pavilion-Laptop-15-cc1xx:44373/]
[rospy.impl.masterslave][INFO] 2020-02-03 22:49:44,111: _ready: http://itachi-HP-Pavilion-Laptop-15-cc1xx:44373/
[rospy.registration][INFO] 2020-02-03 22:49:44,111: Registering with master node http://localhost:11311
[xmlrpc][INFO] 2020-02-03 22:49:44,111: xml rpc node: starting XML-RPC server
[rospy.init][INFO] 2020-02-03 22:49:44,211: registered with master
[rospy.rosout][INFO] 2020-02-03 22:49:44,211: initializing /rosout core topic
[rospy.rosout][INFO] 2020-02-03 22:49:44,213: connected to core topic /rosout
[rospy.simtime][INFO] 2020-02-03 22:49:44,214: /use_sim_time is not set, will not subscribe to simulated time [/clock] topic
[rospy.internal][INFO] 2020-02-03 22:49:44,479: topic[/rosout] adding connection to [/rosout], count 0
[rospy.internal][INFO] 2020-02-03 22:51:54,060: topic[/stats_sr] adding connection to [http://itachi-HP-Pavilion-Laptop-15-cc1xx:38705/], count 0
[rospy.internal][ERROR] 2020-02-03 22:51:59,786: Unable to initiate TCP/IP socket to itachi-HP-Pavilion-Laptop-15-cc1xx:45829 (http://itachi-HP-Pavilion-Laptop-15-cc1xx:38705/): Traceback (most recent call last):
  File "/opt/ros/kinetic/lib/python2.7/dist-packages/rospy/impl/tcpros_base.py", line 557, in connect
    self.read_header()
  File "/opt/ros/kinetic/lib/python2.7/dist-packages/rospy/impl/tcpros_base.py", line 650, in read_header
    self._validate_header(read_ros_handshake_header(sock, self.read_buff, self.protocol.buff_size))
  File "/opt/ros/kinetic/lib/python2.7/dist-packages/rospy/impl/tcpros_base.py", line 593, in _validate_header
    raise TransportInitError("remote error reported: %s"%header['error'])
TransportInitError: remote error reported: node shutting down

[rospy.internal][WARNING] 2020-02-03 22:52:00,788: Unknown error initiating TCP/IP socket to itachi-HP-Pavilion-Laptop-15-cc1xx:45829 (http://itachi-HP-Pavilion-Laptop-15-cc1xx:38705/): Traceback (most recent call last):
  File "/opt/ros/kinetic/lib/python2.7/dist-packages/rospy/impl/tcpros_base.py", line 555, in connect
    self.socket.connect((dest_addr, dest_port))
  File "/usr/lib/python2.7/socket.py", line 228, in meth
    return getattr(self._sock,name)(*args)
error: [Errno 111] Connection refused

[rospy.internal][INFO] 2020-02-03 22:52:00,789: topic[/stats_sr] removing connection to http://itachi-HP-Pavilion-Laptop-15-cc1xx:38705/
[rospy.internal][INFO] 2020-02-03 22:52:18,187: topic[/stats_sr] adding connection to [http://itachi-HP-Pavilion-Laptop-15-cc1xx:43735/], count 0
[rospy.internal][ERROR] 2020-02-03 22:52:24,657: Unable to initiate TCP/IP socket to itachi-HP-Pavilion-Laptop-15-cc1xx:41843 (http://itachi-HP-Pavilion-Laptop-15-cc1xx:43735/): Traceback (most recent call last):
  File "/opt/ros/kinetic/lib/python2.7/dist-packages/rospy/impl/tcpros_base.py", line 557, in connect
    self.read_header()
  File "/opt/ros/kinetic/lib/python2.7/dist-packages/rospy/impl/tcpros_base.py", line 650, in read_header
    self._validate_header(read_ros_handshake_header(sock, self.read_buff, self.protocol.buff_size))
  File "/opt/ros/kinetic/lib/python2.7/dist-packages/rospy/impl/tcpros_base.py", line 593, in _validate_header
    raise TransportInitError("remote error reported: %s"%header['error'])
TransportInitError: remote error reported: node shutting down

[rospy.internal][WARNING] 2020-02-03 22:52:25,658: Unknown error initiating TCP/IP socket to itachi-HP-Pavilion-Laptop-15-cc1xx:41843 (http://itachi-HP-Pavilion-Laptop-15-cc1xx:43735/): Traceback (most recent call last):
  File "/opt/ros/kinetic/lib/python2.7/dist-packages/rospy/impl/tcpros_base.py", line 555, in connect
    self.socket.connect((dest_addr, dest_port))
  File "/usr/lib/python2.7/socket.py", line 228, in meth
    return getattr(self._sock,name)(*args)
error: [Errno 111] Connection refused

[rospy.internal][INFO] 2020-02-03 22:52:25,658: topic[/stats_sr] removing connection to http://itachi-HP-Pavilion-Laptop-15-cc1xx:43735/
[rospy.internal][INFO] 2020-02-03 22:53:06,716: topic[/rosout] removing connection to /rosout
[rospy.core][INFO] 2020-02-03 22:53:55,039: signal_shutdown [signal-2]
[rospy.impl.masterslave][INFO] 2020-02-03 22:53:55,042: signal-2
[rospy.core][INFO] 2020-02-03 22:53:55,207: signal_shutdown [atexit]
