[rospy.client][INFO] 2020-02-02 22:44:35,380: init_node, name[/rostopic_4874_1580663675333], pid[4874]
[xmlrpc][INFO] 2020-02-02 22:44:35,382: XML-RPC server binding to 0.0.0.0:0
[xmlrpc][INFO] 2020-02-02 22:44:35,382: Started XML-RPC server [http://itachi-HP-Pavilion-Laptop-15-cc1xx:46637/]
[rospy.init][INFO] 2020-02-02 22:44:35,382: ROS Slave URI: [http://itachi-HP-Pavilion-Laptop-15-cc1xx:46637/]
[rospy.impl.masterslave][INFO] 2020-02-02 22:44:35,385: _ready: http://itachi-HP-Pavilion-Laptop-15-cc1xx:46637/
[rospy.registration][INFO] 2020-02-02 22:44:35,385: Registering with master node http://localhost:11311
[xmlrpc][INFO] 2020-02-02 22:44:35,385: xml rpc node: starting XML-RPC server
[rospy.init][INFO] 2020-02-02 22:44:35,485: registered with master
[rospy.rosout][INFO] 2020-02-02 22:44:35,486: initializing /rosout core topic
[rospy.rosout][INFO] 2020-02-02 22:44:35,488: connected to core topic /rosout
[rospy.simtime][INFO] 2020-02-02 22:44:35,490: /use_sim_time is not set, will not subscribe to simulated time [/clock] topic
[rospy.internal][INFO] 2020-02-02 22:44:35,590: topic[/detection_info] adding connection to [http://itachi-HP-Pavilion-Laptop-15-cc1xx:46085/], count 0
[rospy.internal][INFO] 2020-02-02 22:44:35,736: topic[/rosout] adding connection to [/rosout], count 0
[rospy.internal][ERROR] 2020-02-02 22:45:24,656: Unable to initiate TCP/IP socket to itachi-HP-Pavilion-Laptop-15-cc1xx:33727 (http://itachi-HP-Pavilion-Laptop-15-cc1xx:46085/): Traceback (most recent call last):
  File "/opt/ros/kinetic/lib/python2.7/dist-packages/rospy/impl/tcpros_base.py", line 557, in connect
    self.read_header()
  File "/opt/ros/kinetic/lib/python2.7/dist-packages/rospy/impl/tcpros_base.py", line 650, in read_header
    self._validate_header(read_ros_handshake_header(sock, self.read_buff, self.protocol.buff_size))
  File "/opt/ros/kinetic/lib/python2.7/dist-packages/rospy/impl/tcpros_base.py", line 593, in _validate_header
    raise TransportInitError("remote error reported: %s"%header['error'])
TransportInitError: remote error reported: node shutting down

[rospy.internal][WARNING] 2020-02-02 22:45:25,675: Unknown error initiating TCP/IP socket to itachi-HP-Pavilion-Laptop-15-cc1xx:33727 (http://itachi-HP-Pavilion-Laptop-15-cc1xx:46085/): Traceback (most recent call last):
  File "/opt/ros/kinetic/lib/python2.7/dist-packages/rospy/impl/tcpros_base.py", line 555, in connect
    self.socket.connect((dest_addr, dest_port))
  File "/usr/lib/python2.7/socket.py", line 228, in meth
    return getattr(self._sock,name)(*args)
error: [Errno 111] Connection refused

[rospy.internal][INFO] 2020-02-02 22:45:25,675: topic[/detection_info] removing connection to http://itachi-HP-Pavilion-Laptop-15-cc1xx:46085/
[rospy.internal][INFO] 2020-02-02 22:46:09,183: topic[/detection_info] adding connection to [http://itachi-HP-Pavilion-Laptop-15-cc1xx:39775/], count 0
[rospy.internal][INFO] 2020-02-02 22:46:14,184: topic[/rosout] removing connection to /rosout
[rospy.internal][WARNING] 2020-02-02 22:46:16,175: Unknown error initiating TCP/IP socket to itachi-HP-Pavilion-Laptop-15-cc1xx:38291 (http://itachi-HP-Pavilion-Laptop-15-cc1xx:39775/): Traceback (most recent call last):
  File "/opt/ros/kinetic/lib/python2.7/dist-packages/rospy/impl/tcpros_base.py", line 557, in connect
    self.read_header()
  File "/opt/ros/kinetic/lib/python2.7/dist-packages/rospy/impl/tcpros_base.py", line 650, in read_header
    self._validate_header(read_ros_handshake_header(sock, self.read_buff, self.protocol.buff_size))
  File "/opt/ros/kinetic/lib/python2.7/dist-packages/rosgraph/network.py", line 362, in read_ros_handshake_header
    d = sock.recv(buff_size)
error: [Errno 104] Connection reset by peer

[rospy.internal][INFO] 2020-02-02 22:46:16,175: topic[/detection_info] removing connection to http://itachi-HP-Pavilion-Laptop-15-cc1xx:39775/
[rospy.core][INFO] 2020-02-02 22:48:42,920: signal_shutdown [signal-2]
[rospy.impl.masterslave][INFO] 2020-02-02 22:48:42,923: signal-2
[rospy.core][INFO] 2020-02-02 22:48:43,055: signal_shutdown [atexit]
