[rospy.client][INFO] 2020-02-04 22:50:48,160: init_node, name[/rostopic_4713_1580836848115], pid[4713]
[xmlrpc][INFO] 2020-02-04 22:50:48,161: XML-RPC server binding to 0.0.0.0:0
[xmlrpc][INFO] 2020-02-04 22:50:48,161: Started XML-RPC server [http://itachi-HP-Pavilion-Laptop-15-cc1xx:33317/]
[rospy.init][INFO] 2020-02-04 22:50:48,161: ROS Slave URI: [http://itachi-HP-Pavilion-Laptop-15-cc1xx:33317/]
[rospy.impl.masterslave][INFO] 2020-02-04 22:50:48,162: _ready: http://itachi-HP-Pavilion-Laptop-15-cc1xx:33317/
[rospy.registration][INFO] 2020-02-04 22:50:48,162: Registering with master node http://localhost:11311
[xmlrpc][INFO] 2020-02-04 22:50:48,162: xml rpc node: starting XML-RPC server
[rospy.init][INFO] 2020-02-04 22:50:48,262: registered with master
[rospy.rosout][INFO] 2020-02-04 22:50:48,262: initializing /rosout core topic
[rospy.rosout][INFO] 2020-02-04 22:50:48,264: connected to core topic /rosout
[rospy.simtime][INFO] 2020-02-04 22:50:48,265: /use_sim_time is not set, will not subscribe to simulated time [/clock] topic
[rospy.internal][INFO] 2020-02-04 22:50:48,480: topic[/rosout] adding connection to [/rosout], count 0
[rospy.internal][INFO] 2020-02-04 22:51:22,512: topic[/detection_info] adding connection to [http://itachi-HP-Pavilion-Laptop-15-cc1xx:44371/], count 0
[rospy.internal][ERROR] 2020-02-04 22:52:36,825: Unable to initiate TCP/IP socket to itachi-HP-Pavilion-Laptop-15-cc1xx:36591 (http://itachi-HP-Pavilion-Laptop-15-cc1xx:44371/): Traceback (most recent call last):
  File "/opt/ros/kinetic/lib/python2.7/dist-packages/rospy/impl/tcpros_base.py", line 557, in connect
    self.read_header()
  File "/opt/ros/kinetic/lib/python2.7/dist-packages/rospy/impl/tcpros_base.py", line 650, in read_header
    self._validate_header(read_ros_handshake_header(sock, self.read_buff, self.protocol.buff_size))
  File "/opt/ros/kinetic/lib/python2.7/dist-packages/rospy/impl/tcpros_base.py", line 593, in _validate_header
    raise TransportInitError("remote error reported: %s"%header['error'])
TransportInitError: remote error reported: node shutting down

[rospy.internal][WARNING] 2020-02-04 22:52:37,847: Unknown error initiating TCP/IP socket to itachi-HP-Pavilion-Laptop-15-cc1xx:36591 (http://itachi-HP-Pavilion-Laptop-15-cc1xx:44371/): Traceback (most recent call last):
  File "/opt/ros/kinetic/lib/python2.7/dist-packages/rospy/impl/tcpros_base.py", line 555, in connect
    self.socket.connect((dest_addr, dest_port))
  File "/usr/lib/python2.7/socket.py", line 228, in meth
    return getattr(self._sock,name)(*args)
error: [Errno 111] Connection refused

[rospy.internal][INFO] 2020-02-04 22:52:37,848: topic[/detection_info] removing connection to http://itachi-HP-Pavilion-Laptop-15-cc1xx:44371/
[rospy.internal][INFO] 2020-02-04 22:52:39,715: topic[/detection_info] adding connection to [http://itachi-HP-Pavilion-Laptop-15-cc1xx:36409/], count 0
[rospy.internal][ERROR] 2020-02-04 22:52:41,424: Unable to initiate TCP/IP socket to itachi-HP-Pavilion-Laptop-15-cc1xx:34575 (http://itachi-HP-Pavilion-Laptop-15-cc1xx:36409/): Traceback (most recent call last):
  File "/opt/ros/kinetic/lib/python2.7/dist-packages/rospy/impl/tcpros_base.py", line 557, in connect
    self.read_header()
  File "/opt/ros/kinetic/lib/python2.7/dist-packages/rospy/impl/tcpros_base.py", line 650, in read_header
    self._validate_header(read_ros_handshake_header(sock, self.read_buff, self.protocol.buff_size))
  File "/opt/ros/kinetic/lib/python2.7/dist-packages/rospy/impl/tcpros_base.py", line 593, in _validate_header
    raise TransportInitError("remote error reported: %s"%header['error'])
TransportInitError: remote error reported: node shutting down

[rospy.internal][WARNING] 2020-02-04 22:52:42,425: Unknown error initiating TCP/IP socket to itachi-HP-Pavilion-Laptop-15-cc1xx:34575 (http://itachi-HP-Pavilion-Laptop-15-cc1xx:36409/): Traceback (most recent call last):
  File "/opt/ros/kinetic/lib/python2.7/dist-packages/rospy/impl/tcpros_base.py", line 555, in connect
    self.socket.connect((dest_addr, dest_port))
  File "/usr/lib/python2.7/socket.py", line 228, in meth
    return getattr(self._sock,name)(*args)
error: [Errno 111] Connection refused

[rospy.internal][INFO] 2020-02-04 22:52:42,425: topic[/detection_info] removing connection to http://itachi-HP-Pavilion-Laptop-15-cc1xx:36409/
[rospy.internal][INFO] 2020-02-04 22:52:51,836: topic[/detection_info] adding connection to [http://itachi-HP-Pavilion-Laptop-15-cc1xx:39915/], count 0
[rospy.internal][ERROR] 2020-02-04 22:52:54,167: Unable to initiate TCP/IP socket to itachi-HP-Pavilion-Laptop-15-cc1xx:42683 (http://itachi-HP-Pavilion-Laptop-15-cc1xx:39915/): Traceback (most recent call last):
  File "/opt/ros/kinetic/lib/python2.7/dist-packages/rospy/impl/tcpros_base.py", line 557, in connect
    self.read_header()
  File "/opt/ros/kinetic/lib/python2.7/dist-packages/rospy/impl/tcpros_base.py", line 650, in read_header
    self._validate_header(read_ros_handshake_header(sock, self.read_buff, self.protocol.buff_size))
  File "/opt/ros/kinetic/lib/python2.7/dist-packages/rospy/impl/tcpros_base.py", line 593, in _validate_header
    raise TransportInitError("remote error reported: %s"%header['error'])
TransportInitError: remote error reported: node shutting down

[rospy.internal][WARNING] 2020-02-04 22:52:55,169: Unknown error initiating TCP/IP socket to itachi-HP-Pavilion-Laptop-15-cc1xx:42683 (http://itachi-HP-Pavilion-Laptop-15-cc1xx:39915/): Traceback (most recent call last):
  File "/opt/ros/kinetic/lib/python2.7/dist-packages/rospy/impl/tcpros_base.py", line 555, in connect
    self.socket.connect((dest_addr, dest_port))
  File "/usr/lib/python2.7/socket.py", line 228, in meth
    return getattr(self._sock,name)(*args)
error: [Errno 111] Connection refused

[rospy.internal][INFO] 2020-02-04 22:52:55,170: topic[/detection_info] removing connection to http://itachi-HP-Pavilion-Laptop-15-cc1xx:39915/
[rospy.internal][INFO] 2020-02-04 22:53:28,670: topic[/detection_info] adding connection to [http://itachi-HP-Pavilion-Laptop-15-cc1xx:41883/], count 0
[rospy.internal][ERROR] 2020-02-04 22:53:30,746: Unable to initiate TCP/IP socket to itachi-HP-Pavilion-Laptop-15-cc1xx:39135 (http://itachi-HP-Pavilion-Laptop-15-cc1xx:41883/): Traceback (most recent call last):
  File "/opt/ros/kinetic/lib/python2.7/dist-packages/rospy/impl/tcpros_base.py", line 557, in connect
    self.read_header()
  File "/opt/ros/kinetic/lib/python2.7/dist-packages/rospy/impl/tcpros_base.py", line 650, in read_header
    self._validate_header(read_ros_handshake_header(sock, self.read_buff, self.protocol.buff_size))
  File "/opt/ros/kinetic/lib/python2.7/dist-packages/rospy/impl/tcpros_base.py", line 593, in _validate_header
    raise TransportInitError("remote error reported: %s"%header['error'])
TransportInitError: remote error reported: node shutting down

[rospy.internal][WARNING] 2020-02-04 22:53:31,748: Unknown error initiating TCP/IP socket to itachi-HP-Pavilion-Laptop-15-cc1xx:39135 (http://itachi-HP-Pavilion-Laptop-15-cc1xx:41883/): Traceback (most recent call last):
  File "/opt/ros/kinetic/lib/python2.7/dist-packages/rospy/impl/tcpros_base.py", line 555, in connect
    self.socket.connect((dest_addr, dest_port))
  File "/usr/lib/python2.7/socket.py", line 228, in meth
    return getattr(self._sock,name)(*args)
error: [Errno 111] Connection refused

[rospy.internal][INFO] 2020-02-04 22:53:31,748: topic[/detection_info] removing connection to http://itachi-HP-Pavilion-Laptop-15-cc1xx:41883/
[rospy.internal][INFO] 2020-02-04 22:55:21,691: topic[/detection_info] adding connection to [http://itachi-HP-Pavilion-Laptop-15-cc1xx:34049/], count 0
[rospy.internal][ERROR] 2020-02-04 22:55:52,063: Unable to initiate TCP/IP socket to itachi-HP-Pavilion-Laptop-15-cc1xx:35637 (http://itachi-HP-Pavilion-Laptop-15-cc1xx:34049/): Traceback (most recent call last):
  File "/opt/ros/kinetic/lib/python2.7/dist-packages/rospy/impl/tcpros_base.py", line 557, in connect
    self.read_header()
  File "/opt/ros/kinetic/lib/python2.7/dist-packages/rospy/impl/tcpros_base.py", line 650, in read_header
    self._validate_header(read_ros_handshake_header(sock, self.read_buff, self.protocol.buff_size))
  File "/opt/ros/kinetic/lib/python2.7/dist-packages/rospy/impl/tcpros_base.py", line 593, in _validate_header
    raise TransportInitError("remote error reported: %s"%header['error'])
TransportInitError: remote error reported: node shutting down

[rospy.internal][WARNING] 2020-02-04 22:55:53,064: Unknown error initiating TCP/IP socket to itachi-HP-Pavilion-Laptop-15-cc1xx:35637 (http://itachi-HP-Pavilion-Laptop-15-cc1xx:34049/): Traceback (most recent call last):
  File "/opt/ros/kinetic/lib/python2.7/dist-packages/rospy/impl/tcpros_base.py", line 555, in connect
    self.socket.connect((dest_addr, dest_port))
  File "/usr/lib/python2.7/socket.py", line 228, in meth
    return getattr(self._sock,name)(*args)
error: [Errno 111] Connection refused

[rospy.internal][INFO] 2020-02-04 22:55:53,064: topic[/detection_info] removing connection to http://itachi-HP-Pavilion-Laptop-15-cc1xx:34049/
[rospy.internal][INFO] 2020-02-04 22:56:50,559: topic[/detection_info] adding connection to [http://itachi-HP-Pavilion-Laptop-15-cc1xx:37917/], count 0
[rospy.internal][ERROR] 2020-02-04 22:56:52,432: Unable to initiate TCP/IP socket to itachi-HP-Pavilion-Laptop-15-cc1xx:42805 (http://itachi-HP-Pavilion-Laptop-15-cc1xx:37917/): Traceback (most recent call last):
  File "/opt/ros/kinetic/lib/python2.7/dist-packages/rospy/impl/tcpros_base.py", line 557, in connect
    self.read_header()
  File "/opt/ros/kinetic/lib/python2.7/dist-packages/rospy/impl/tcpros_base.py", line 650, in read_header
    self._validate_header(read_ros_handshake_header(sock, self.read_buff, self.protocol.buff_size))
  File "/opt/ros/kinetic/lib/python2.7/dist-packages/rospy/impl/tcpros_base.py", line 593, in _validate_header
    raise TransportInitError("remote error reported: %s"%header['error'])
TransportInitError: remote error reported: node shutting down

[rospy.internal][WARNING] 2020-02-04 22:56:53,433: Unknown error initiating TCP/IP socket to itachi-HP-Pavilion-Laptop-15-cc1xx:42805 (http://itachi-HP-Pavilion-Laptop-15-cc1xx:37917/): Traceback (most recent call last):
  File "/opt/ros/kinetic/lib/python2.7/dist-packages/rospy/impl/tcpros_base.py", line 555, in connect
    self.socket.connect((dest_addr, dest_port))
  File "/usr/lib/python2.7/socket.py", line 228, in meth
    return getattr(self._sock,name)(*args)
error: [Errno 111] Connection refused

[rospy.internal][INFO] 2020-02-04 22:56:53,433: topic[/detection_info] removing connection to http://itachi-HP-Pavilion-Laptop-15-cc1xx:37917/
[rospy.internal][INFO] 2020-02-04 22:57:27,394: topic[/detection_info] adding connection to [http://itachi-HP-Pavilion-Laptop-15-cc1xx:41363/], count 0
[rospy.internal][ERROR] 2020-02-04 22:57:28,815: Unable to initiate TCP/IP socket to itachi-HP-Pavilion-Laptop-15-cc1xx:37811 (http://itachi-HP-Pavilion-Laptop-15-cc1xx:41363/): Traceback (most recent call last):
  File "/opt/ros/kinetic/lib/python2.7/dist-packages/rospy/impl/tcpros_base.py", line 557, in connect
    self.read_header()
  File "/opt/ros/kinetic/lib/python2.7/dist-packages/rospy/impl/tcpros_base.py", line 650, in read_header
    self._validate_header(read_ros_handshake_header(sock, self.read_buff, self.protocol.buff_size))
  File "/opt/ros/kinetic/lib/python2.7/dist-packages/rospy/impl/tcpros_base.py", line 593, in _validate_header
    raise TransportInitError("remote error reported: %s"%header['error'])
TransportInitError: remote error reported: node shutting down

[rospy.internal][WARNING] 2020-02-04 22:57:29,816: Unknown error initiating TCP/IP socket to itachi-HP-Pavilion-Laptop-15-cc1xx:37811 (http://itachi-HP-Pavilion-Laptop-15-cc1xx:41363/): Traceback (most recent call last):
  File "/opt/ros/kinetic/lib/python2.7/dist-packages/rospy/impl/tcpros_base.py", line 555, in connect
    self.socket.connect((dest_addr, dest_port))
  File "/usr/lib/python2.7/socket.py", line 228, in meth
    return getattr(self._sock,name)(*args)
error: [Errno 111] Connection refused

[rospy.internal][INFO] 2020-02-04 22:57:29,816: topic[/detection_info] removing connection to http://itachi-HP-Pavilion-Laptop-15-cc1xx:41363/
[rospy.internal][INFO] 2020-02-04 22:57:51,776: topic[/detection_info] adding connection to [http://itachi-HP-Pavilion-Laptop-15-cc1xx:35439/], count 0
[rospy.core][INFO] 2020-02-04 22:57:54,794: signal_shutdown [signal-2]
[rospy.internal][INFO] 2020-02-04 22:57:54,796: topic[/rosout] removing connection to /rosout
[rospy.internal][INFO] 2020-02-04 22:57:54,796: topic[/detection_info] removing connection to http://itachi-HP-Pavilion-Laptop-15-cc1xx:35439/
[rospy.impl.masterslave][INFO] 2020-02-04 22:57:54,797: signal-2
[rospy.core][INFO] 2020-02-04 22:57:54,913: signal_shutdown [atexit]
