[rospy.client][INFO] 2020-02-27 15:50:20,564: init_node, name[/rostopic_31808_1582798820519], pid[31808]
[xmlrpc][INFO] 2020-02-27 15:50:20,565: XML-RPC server binding to 0.0.0.0:0
[xmlrpc][INFO] 2020-02-27 15:50:20,565: Started XML-RPC server [http://itachi-HP-Pavilion-Laptop-15-cc1xx:34477/]
[rospy.init][INFO] 2020-02-27 15:50:20,566: ROS Slave URI: [http://itachi-HP-Pavilion-Laptop-15-cc1xx:34477/]
[rospy.impl.masterslave][INFO] 2020-02-27 15:50:20,566: _ready: http://itachi-HP-Pavilion-Laptop-15-cc1xx:34477/
[xmlrpc][INFO] 2020-02-27 15:50:20,566: xml rpc node: starting XML-RPC server
[rospy.registration][INFO] 2020-02-27 15:50:20,566: Registering with master node http://localhost:11311
[rospy.init][INFO] 2020-02-27 15:50:20,666: registered with master
[rospy.rosout][INFO] 2020-02-27 15:50:20,667: initializing /rosout core topic
[rospy.rosout][INFO] 2020-02-27 15:50:20,669: connected to core topic /rosout
[rospy.simtime][INFO] 2020-02-27 15:50:20,670: /use_sim_time is not set, will not subscribe to simulated time [/clock] topic
[rospy.internal][INFO] 2020-02-27 15:50:20,737: topic[/serviced_info] adding connection to [http://itachi-HP-Pavilion-Laptop-15-cc1xx:36609/], count 0
[rospy.internal][INFO] 2020-02-27 15:50:20,945: topic[/rosout] adding connection to [/rosout], count 0
[rospy.internal][ERROR] 2020-02-27 15:50:26,544: Unable to initiate TCP/IP socket to itachi-HP-Pavilion-Laptop-15-cc1xx:40275 (http://itachi-HP-Pavilion-Laptop-15-cc1xx:36609/): Traceback (most recent call last):
  File "/opt/ros/kinetic/lib/python2.7/dist-packages/rospy/impl/tcpros_base.py", line 557, in connect
    self.read_header()
  File "/opt/ros/kinetic/lib/python2.7/dist-packages/rospy/impl/tcpros_base.py", line 650, in read_header
    self._validate_header(read_ros_handshake_header(sock, self.read_buff, self.protocol.buff_size))
  File "/opt/ros/kinetic/lib/python2.7/dist-packages/rospy/impl/tcpros_base.py", line 593, in _validate_header
    raise TransportInitError("remote error reported: %s"%header['error'])
TransportInitError: remote error reported: node shutting down

[rospy.internal][WARNING] 2020-02-27 15:50:27,546: Unknown error initiating TCP/IP socket to itachi-HP-Pavilion-Laptop-15-cc1xx:40275 (http://itachi-HP-Pavilion-Laptop-15-cc1xx:36609/): Traceback (most recent call last):
  File "/opt/ros/kinetic/lib/python2.7/dist-packages/rospy/impl/tcpros_base.py", line 555, in connect
    self.socket.connect((dest_addr, dest_port))
  File "/usr/lib/python2.7/socket.py", line 228, in meth
    return getattr(self._sock,name)(*args)
error: [Errno 111] Connection refused

[rospy.internal][INFO] 2020-02-27 15:50:27,546: topic[/serviced_info] removing connection to http://itachi-HP-Pavilion-Laptop-15-cc1xx:36609/
[rospy.internal][INFO] 2020-02-27 15:50:32,776: topic[/serviced_info] adding connection to [http://itachi-HP-Pavilion-Laptop-15-cc1xx:45921/], count 0
[rospy.internal][INFO] 2020-02-27 15:53:36,370: topic[/rosout] removing connection to /rosout
[rospy.internal][ERROR] 2020-02-27 15:53:36,463: Unable to initiate TCP/IP socket to itachi-HP-Pavilion-Laptop-15-cc1xx:37769 (http://itachi-HP-Pavilion-Laptop-15-cc1xx:45921/): Traceback (most recent call last):
  File "/opt/ros/kinetic/lib/python2.7/dist-packages/rospy/impl/tcpros_base.py", line 557, in connect
    self.read_header()
  File "/opt/ros/kinetic/lib/python2.7/dist-packages/rospy/impl/tcpros_base.py", line 650, in read_header
    self._validate_header(read_ros_handshake_header(sock, self.read_buff, self.protocol.buff_size))
  File "/opt/ros/kinetic/lib/python2.7/dist-packages/rospy/impl/tcpros_base.py", line 593, in _validate_header
    raise TransportInitError("remote error reported: %s"%header['error'])
TransportInitError: remote error reported: node shutting down

[rospy.internal][WARNING] 2020-02-27 15:53:37,465: Unknown error initiating TCP/IP socket to itachi-HP-Pavilion-Laptop-15-cc1xx:37769 (http://itachi-HP-Pavilion-Laptop-15-cc1xx:45921/): Traceback (most recent call last):
  File "/opt/ros/kinetic/lib/python2.7/dist-packages/rospy/impl/tcpros_base.py", line 555, in connect
    self.socket.connect((dest_addr, dest_port))
  File "/usr/lib/python2.7/socket.py", line 228, in meth
    return getattr(self._sock,name)(*args)
error: [Errno 111] Connection refused

[rospy.internal][INFO] 2020-02-27 15:53:37,465: topic[/serviced_info] removing connection to http://itachi-HP-Pavilion-Laptop-15-cc1xx:45921/
[rospy.core][INFO] 2020-02-27 15:54:15,071: signal_shutdown [signal-2]
[rospy.impl.masterslave][INFO] 2020-02-27 15:54:15,076: signal-2
[rospy.core][INFO] 2020-02-27 15:54:15,208: signal_shutdown [atexit]
