[rospy.client][INFO] 2020-02-26 21:55:43,868: init_node, name[/rostopic_9822_1582734343833], pid[9822]
[xmlrpc][INFO] 2020-02-26 21:55:43,868: XML-RPC server binding to 0.0.0.0:0
[xmlrpc][INFO] 2020-02-26 21:55:43,868: Started XML-RPC server [http://itachi-HP-Pavilion-Laptop-15-cc1xx:38337/]
[rospy.init][INFO] 2020-02-26 21:55:43,869: ROS Slave URI: [http://itachi-HP-Pavilion-Laptop-15-cc1xx:38337/]
[rospy.impl.masterslave][INFO] 2020-02-26 21:55:43,869: _ready: http://itachi-HP-Pavilion-Laptop-15-cc1xx:38337/
[rospy.registration][INFO] 2020-02-26 21:55:43,869: Registering with master node http://localhost:11311
[xmlrpc][INFO] 2020-02-26 21:55:43,869: xml rpc node: starting XML-RPC server
[rospy.init][INFO] 2020-02-26 21:55:43,969: registered with master
[rospy.rosout][INFO] 2020-02-26 21:55:43,969: initializing /rosout core topic
[rospy.rosout][INFO] 2020-02-26 21:55:43,971: connected to core topic /rosout
[rospy.simtime][INFO] 2020-02-26 21:55:43,971: /use_sim_time is not set, will not subscribe to simulated time [/clock] topic
[rospy.internal][INFO] 2020-02-26 21:55:44,267: topic[/rosout] adding connection to [/rosout], count 0
[rospy.internal][INFO] 2020-02-26 21:55:47,790: topic[/serviced_info] adding connection to [http://itachi-HP-Pavilion-Laptop-15-cc1xx:45831/], count 0
[rospy.internal][ERROR] 2020-02-26 21:56:54,315: Unable to initiate TCP/IP socket to itachi-HP-Pavilion-Laptop-15-cc1xx:36597 (http://itachi-HP-Pavilion-Laptop-15-cc1xx:45831/): Traceback (most recent call last):
  File "/opt/ros/kinetic/lib/python2.7/dist-packages/rospy/impl/tcpros_base.py", line 557, in connect
    self.read_header()
  File "/opt/ros/kinetic/lib/python2.7/dist-packages/rospy/impl/tcpros_base.py", line 650, in read_header
    self._validate_header(read_ros_handshake_header(sock, self.read_buff, self.protocol.buff_size))
  File "/opt/ros/kinetic/lib/python2.7/dist-packages/rospy/impl/tcpros_base.py", line 593, in _validate_header
    raise TransportInitError("remote error reported: %s"%header['error'])
TransportInitError: remote error reported: node shutting down

[rospy.internal][WARNING] 2020-02-26 21:56:55,316: Unknown error initiating TCP/IP socket to itachi-HP-Pavilion-Laptop-15-cc1xx:36597 (http://itachi-HP-Pavilion-Laptop-15-cc1xx:45831/): Traceback (most recent call last):
  File "/opt/ros/kinetic/lib/python2.7/dist-packages/rospy/impl/tcpros_base.py", line 555, in connect
    self.socket.connect((dest_addr, dest_port))
  File "/usr/lib/python2.7/socket.py", line 228, in meth
    return getattr(self._sock,name)(*args)
error: [Errno 111] Connection refused

[rospy.internal][INFO] 2020-02-26 21:56:55,316: topic[/serviced_info] removing connection to http://itachi-HP-Pavilion-Laptop-15-cc1xx:45831/
[rospy.core][INFO] 2020-02-26 21:56:56,503: signal_shutdown [signal-2]
[rospy.internal][INFO] 2020-02-26 21:56:56,507: topic[/rosout] removing connection to /rosout
[rospy.impl.masterslave][INFO] 2020-02-26 21:56:56,508: signal-2
[rospy.core][INFO] 2020-02-26 21:56:56,672: signal_shutdown [atexit]
