[rospy.client][INFO] 2020-02-28 17:43:50,584: init_node, name[/rostopic_11325_1582892030532], pid[11325]
[xmlrpc][INFO] 2020-02-28 17:43:50,586: XML-RPC server binding to 0.0.0.0:0
[xmlrpc][INFO] 2020-02-28 17:43:50,586: Started XML-RPC server [http://itachi-HP-Pavilion-Laptop-15-cc1xx:45069/]
[rospy.init][INFO] 2020-02-28 17:43:50,586: ROS Slave URI: [http://itachi-HP-Pavilion-Laptop-15-cc1xx:45069/]
[rospy.impl.masterslave][INFO] 2020-02-28 17:43:50,587: _ready: http://itachi-HP-Pavilion-Laptop-15-cc1xx:45069/
[rospy.registration][INFO] 2020-02-28 17:43:50,587: Registering with master node http://localhost:11311
[xmlrpc][INFO] 2020-02-28 17:43:50,587: xml rpc node: starting XML-RPC server
[rospy.init][INFO] 2020-02-28 17:43:50,687: registered with master
[rospy.rosout][INFO] 2020-02-28 17:43:50,687: initializing /rosout core topic
[rospy.rosout][INFO] 2020-02-28 17:43:50,690: connected to core topic /rosout
[rospy.simtime][INFO] 2020-02-28 17:43:50,692: /use_sim_time is not set, will not subscribe to simulated time [/clock] topic
[rospy.internal][INFO] 2020-02-28 17:43:50,757: topic[/stats_sr] adding connection to [http://itachi-HP-Pavilion-Laptop-15-cc1xx:44371/], count 0
[rospy.internal][INFO] 2020-02-28 17:43:50,964: topic[/rosout] adding connection to [/rosout], count 0
[rospy.internal][ERROR] 2020-02-28 17:44:29,576: Unable to initiate TCP/IP socket to itachi-HP-Pavilion-Laptop-15-cc1xx:39605 (http://itachi-HP-Pavilion-Laptop-15-cc1xx:44371/): Traceback (most recent call last):
  File "/opt/ros/kinetic/lib/python2.7/dist-packages/rospy/impl/tcpros_base.py", line 557, in connect
    self.read_header()
  File "/opt/ros/kinetic/lib/python2.7/dist-packages/rospy/impl/tcpros_base.py", line 650, in read_header
    self._validate_header(read_ros_handshake_header(sock, self.read_buff, self.protocol.buff_size))
  File "/opt/ros/kinetic/lib/python2.7/dist-packages/rospy/impl/tcpros_base.py", line 593, in _validate_header
    raise TransportInitError("remote error reported: %s"%header['error'])
TransportInitError: remote error reported: node shutting down

[rospy.internal][WARNING] 2020-02-28 17:44:30,577: Unknown error initiating TCP/IP socket to itachi-HP-Pavilion-Laptop-15-cc1xx:39605 (http://itachi-HP-Pavilion-Laptop-15-cc1xx:44371/): Traceback (most recent call last):
  File "/opt/ros/kinetic/lib/python2.7/dist-packages/rospy/impl/tcpros_base.py", line 555, in connect
    self.socket.connect((dest_addr, dest_port))
  File "/usr/lib/python2.7/socket.py", line 228, in meth
    return getattr(self._sock,name)(*args)
error: [Errno 111] Connection refused

[rospy.internal][INFO] 2020-02-28 17:44:30,577: topic[/stats_sr] removing connection to http://itachi-HP-Pavilion-Laptop-15-cc1xx:44371/
[rospy.internal][INFO] 2020-02-28 17:44:52,283: topic[/rosout] removing connection to /rosout
[rospy.core][INFO] 2020-02-28 17:44:56,695: signal_shutdown [signal-2]
[rospy.registration][WARNING] 2020-02-28 17:44:56,697: cannot unregister with master due to network issues
[rospy.impl.masterslave][INFO] 2020-02-28 17:44:56,697: signal-2
[rospy.core][INFO] 2020-02-28 17:44:56,806: signal_shutdown [atexit]
