[rospy.client][INFO] 2020-02-27 14:38:37,866: init_node, name[/rostopic_21769_1582794517824], pid[21769]
[xmlrpc][INFO] 2020-02-27 14:38:37,866: XML-RPC server binding to 0.0.0.0:0
[xmlrpc][INFO] 2020-02-27 14:38:37,867: Started XML-RPC server [http://itachi-HP-Pavilion-Laptop-15-cc1xx:44243/]
[rospy.init][INFO] 2020-02-27 14:38:37,867: ROS Slave URI: [http://itachi-HP-Pavilion-Laptop-15-cc1xx:44243/]
[rospy.impl.masterslave][INFO] 2020-02-27 14:38:37,867: _ready: http://itachi-HP-Pavilion-Laptop-15-cc1xx:44243/
[rospy.registration][INFO] 2020-02-27 14:38:37,867: Registering with master node http://localhost:11311
[xmlrpc][INFO] 2020-02-27 14:38:37,867: xml rpc node: starting XML-RPC server
[rospy.init][INFO] 2020-02-27 14:38:37,967: registered with master
[rospy.rosout][INFO] 2020-02-27 14:38:37,967: initializing /rosout core topic
[rospy.rosout][INFO] 2020-02-27 14:38:37,970: connected to core topic /rosout
[rospy.simtime][INFO] 2020-02-27 14:38:37,972: /use_sim_time is not set, will not subscribe to simulated time [/clock] topic
[rospy.internal][INFO] 2020-02-27 14:38:38,233: topic[/rosout] adding connection to [/rosout], count 0
[rospy.internal][INFO] 2020-02-27 14:38:45,738: topic[/serviced_info] adding connection to [http://itachi-HP-Pavilion-Laptop-15-cc1xx:42739/], count 0
[rospy.internal][ERROR] 2020-02-27 14:40:14,586: Unable to initiate TCP/IP socket to itachi-HP-Pavilion-Laptop-15-cc1xx:36705 (http://itachi-HP-Pavilion-Laptop-15-cc1xx:42739/): Traceback (most recent call last):
  File "/opt/ros/kinetic/lib/python2.7/dist-packages/rospy/impl/tcpros_base.py", line 557, in connect
    self.read_header()
  File "/opt/ros/kinetic/lib/python2.7/dist-packages/rospy/impl/tcpros_base.py", line 650, in read_header
    self._validate_header(read_ros_handshake_header(sock, self.read_buff, self.protocol.buff_size))
  File "/opt/ros/kinetic/lib/python2.7/dist-packages/rospy/impl/tcpros_base.py", line 593, in _validate_header
    raise TransportInitError("remote error reported: %s"%header['error'])
TransportInitError: remote error reported: node shutting down

[rospy.internal][WARNING] 2020-02-27 14:40:15,588: Unknown error initiating TCP/IP socket to itachi-HP-Pavilion-Laptop-15-cc1xx:36705 (http://itachi-HP-Pavilion-Laptop-15-cc1xx:42739/): Traceback (most recent call last):
  File "/opt/ros/kinetic/lib/python2.7/dist-packages/rospy/impl/tcpros_base.py", line 555, in connect
    self.socket.connect((dest_addr, dest_port))
  File "/usr/lib/python2.7/socket.py", line 228, in meth
    return getattr(self._sock,name)(*args)
error: [Errno 111] Connection refused

[rospy.internal][INFO] 2020-02-27 14:40:15,588: topic[/serviced_info] removing connection to http://itachi-HP-Pavilion-Laptop-15-cc1xx:42739/
[rospy.internal][INFO] 2020-02-27 14:42:33,378: topic[/serviced_info] adding connection to [http://itachi-HP-Pavilion-Laptop-15-cc1xx:43259/], count 0
[rospy.internal][ERROR] 2020-02-27 14:45:39,158: Unable to initiate TCP/IP socket to itachi-HP-Pavilion-Laptop-15-cc1xx:35709 (http://itachi-HP-Pavilion-Laptop-15-cc1xx:43259/): Traceback (most recent call last):
  File "/opt/ros/kinetic/lib/python2.7/dist-packages/rospy/impl/tcpros_base.py", line 557, in connect
    self.read_header()
  File "/opt/ros/kinetic/lib/python2.7/dist-packages/rospy/impl/tcpros_base.py", line 650, in read_header
    self._validate_header(read_ros_handshake_header(sock, self.read_buff, self.protocol.buff_size))
  File "/opt/ros/kinetic/lib/python2.7/dist-packages/rospy/impl/tcpros_base.py", line 593, in _validate_header
    raise TransportInitError("remote error reported: %s"%header['error'])
TransportInitError: remote error reported: node shutting down

[rospy.internal][WARNING] 2020-02-27 14:45:40,161: Unknown error initiating TCP/IP socket to itachi-HP-Pavilion-Laptop-15-cc1xx:35709 (http://itachi-HP-Pavilion-Laptop-15-cc1xx:43259/): Traceback (most recent call last):
  File "/opt/ros/kinetic/lib/python2.7/dist-packages/rospy/impl/tcpros_base.py", line 555, in connect
    self.socket.connect((dest_addr, dest_port))
  File "/usr/lib/python2.7/socket.py", line 228, in meth
    return getattr(self._sock,name)(*args)
error: [Errno 111] Connection refused

[rospy.internal][INFO] 2020-02-27 14:45:40,162: topic[/serviced_info] removing connection to http://itachi-HP-Pavilion-Laptop-15-cc1xx:43259/
[rospy.core][INFO] 2020-02-27 14:46:33,238: signal_shutdown [signal-2]
[rospy.internal][INFO] 2020-02-27 14:46:33,242: topic[/rosout] removing connection to /rosout
[rospy.impl.masterslave][INFO] 2020-02-27 14:46:33,242: signal-2
[rospy.core][INFO] 2020-02-27 14:46:33,374: signal_shutdown [atexit]
