[rospy.client][INFO] 2020-02-28 18:06:10,765: init_node, name[/rostopic_6884_1582893370711], pid[6884]
[xmlrpc][INFO] 2020-02-28 18:06:10,765: XML-RPC server binding to 0.0.0.0:0
[xmlrpc][INFO] 2020-02-28 18:06:10,766: Started XML-RPC server [http://itachi-HP-Pavilion-Laptop-15-cc1xx:43643/]
[rospy.init][INFO] 2020-02-28 18:06:10,766: ROS Slave URI: [http://itachi-HP-Pavilion-Laptop-15-cc1xx:43643/]
[rospy.impl.masterslave][INFO] 2020-02-28 18:06:10,766: _ready: http://itachi-HP-Pavilion-Laptop-15-cc1xx:43643/
[rospy.registration][INFO] 2020-02-28 18:06:10,766: Registering with master node http://localhost:11311
[xmlrpc][INFO] 2020-02-28 18:06:10,766: xml rpc node: starting XML-RPC server
[rospy.init][INFO] 2020-02-28 18:06:10,866: registered with master
[rospy.rosout][INFO] 2020-02-28 18:06:10,866: initializing /rosout core topic
[rospy.rosout][INFO] 2020-02-28 18:06:10,868: connected to core topic /rosout
[rospy.simtime][INFO] 2020-02-28 18:06:10,873: /use_sim_time is not set, will not subscribe to simulated time [/clock] topic
[rospy.internal][INFO] 2020-02-28 18:06:10,935: topic[/stats_sr] adding connection to [http://itachi-HP-Pavilion-Laptop-15-cc1xx:40221/], count 0
[rospy.internal][INFO] 2020-02-28 18:06:11,072: topic[/rosout] adding connection to [/rosout], count 0
[rospy.internal][ERROR] 2020-02-28 18:08:12,849: Unable to initiate TCP/IP socket to itachi-HP-Pavilion-Laptop-15-cc1xx:40837 (http://itachi-HP-Pavilion-Laptop-15-cc1xx:40221/): Traceback (most recent call last):
  File "/opt/ros/kinetic/lib/python2.7/dist-packages/rospy/impl/tcpros_base.py", line 557, in connect
    self.read_header()
  File "/opt/ros/kinetic/lib/python2.7/dist-packages/rospy/impl/tcpros_base.py", line 650, in read_header
    self._validate_header(read_ros_handshake_header(sock, self.read_buff, self.protocol.buff_size))
  File "/opt/ros/kinetic/lib/python2.7/dist-packages/rospy/impl/tcpros_base.py", line 593, in _validate_header
    raise TransportInitError("remote error reported: %s"%header['error'])
TransportInitError: remote error reported: node shutting down

[rospy.internal][WARNING] 2020-02-28 18:08:13,850: Unknown error initiating TCP/IP socket to itachi-HP-Pavilion-Laptop-15-cc1xx:40837 (http://itachi-HP-Pavilion-Laptop-15-cc1xx:40221/): Traceback (most recent call last):
  File "/opt/ros/kinetic/lib/python2.7/dist-packages/rospy/impl/tcpros_base.py", line 555, in connect
    self.socket.connect((dest_addr, dest_port))
  File "/usr/lib/python2.7/socket.py", line 228, in meth
    return getattr(self._sock,name)(*args)
error: [Errno 111] Connection refused

[rospy.internal][INFO] 2020-02-28 18:08:13,850: topic[/stats_sr] removing connection to http://itachi-HP-Pavilion-Laptop-15-cc1xx:40221/
[rospy.core][INFO] 2020-02-28 18:08:24,879: signal_shutdown [signal-2]
[rospy.internal][INFO] 2020-02-28 18:08:24,883: topic[/rosout] removing connection to /rosout
[rospy.impl.masterslave][INFO] 2020-02-28 18:08:24,883: signal-2
[rospy.core][INFO] 2020-02-28 18:08:25,016: signal_shutdown [atexit]
