[rospy.client][INFO] 2020-02-27 14:46:29,840: init_node, name[/rostopic_22720_1582794989805], pid[22720]
[xmlrpc][INFO] 2020-02-27 14:46:29,841: XML-RPC server binding to 0.0.0.0:0
[xmlrpc][INFO] 2020-02-27 14:46:29,841: Started XML-RPC server [http://itachi-HP-Pavilion-Laptop-15-cc1xx:45479/]
[rospy.init][INFO] 2020-02-27 14:46:29,841: ROS Slave URI: [http://itachi-HP-Pavilion-Laptop-15-cc1xx:45479/]
[rospy.impl.masterslave][INFO] 2020-02-27 14:46:29,842: _ready: http://itachi-HP-Pavilion-Laptop-15-cc1xx:45479/
[rospy.registration][INFO] 2020-02-27 14:46:29,842: Registering with master node http://localhost:11311
[xmlrpc][INFO] 2020-02-27 14:46:29,843: xml rpc node: starting XML-RPC server
[rospy.init][INFO] 2020-02-27 14:46:29,942: registered with master
[rospy.rosout][INFO] 2020-02-27 14:46:29,942: initializing /rosout core topic
[rospy.rosout][INFO] 2020-02-27 14:46:29,944: connected to core topic /rosout
[rospy.simtime][INFO] 2020-02-27 14:46:29,946: /use_sim_time is not set, will not subscribe to simulated time [/clock] topic
[rospy.internal][INFO] 2020-02-27 14:46:30,187: topic[/rosout] adding connection to [/rosout], count 0
[rospy.internal][INFO] 2020-02-27 14:46:45,980: topic[/decision_info] adding connection to [http://itachi-HP-Pavilion-Laptop-15-cc1xx:40557/], count 0
[rospy.internal][ERROR] 2020-02-27 14:50:00,280: Unable to initiate TCP/IP socket to itachi-HP-Pavilion-Laptop-15-cc1xx:36825 (http://itachi-HP-Pavilion-Laptop-15-cc1xx:40557/): Traceback (most recent call last):
  File "/opt/ros/kinetic/lib/python2.7/dist-packages/rospy/impl/tcpros_base.py", line 557, in connect
    self.read_header()
  File "/opt/ros/kinetic/lib/python2.7/dist-packages/rospy/impl/tcpros_base.py", line 650, in read_header
    self._validate_header(read_ros_handshake_header(sock, self.read_buff, self.protocol.buff_size))
  File "/opt/ros/kinetic/lib/python2.7/dist-packages/rospy/impl/tcpros_base.py", line 593, in _validate_header
    raise TransportInitError("remote error reported: %s"%header['error'])
TransportInitError: remote error reported: node shutting down

[rospy.internal][WARNING] 2020-02-27 14:50:01,282: Unknown error initiating TCP/IP socket to itachi-HP-Pavilion-Laptop-15-cc1xx:36825 (http://itachi-HP-Pavilion-Laptop-15-cc1xx:40557/): Traceback (most recent call last):
  File "/opt/ros/kinetic/lib/python2.7/dist-packages/rospy/impl/tcpros_base.py", line 555, in connect
    self.socket.connect((dest_addr, dest_port))
  File "/usr/lib/python2.7/socket.py", line 228, in meth
    return getattr(self._sock,name)(*args)
error: [Errno 111] Connection refused

[rospy.internal][INFO] 2020-02-27 14:50:01,282: topic[/decision_info] removing connection to http://itachi-HP-Pavilion-Laptop-15-cc1xx:40557/
[rospy.internal][INFO] 2020-02-27 14:50:03,498: topic[/decision_info] adding connection to [http://itachi-HP-Pavilion-Laptop-15-cc1xx:41641/], count 0
[rospy.core][INFO] 2020-02-27 14:50:32,928: signal_shutdown [signal-2]
[rospy.internal][INFO] 2020-02-27 14:50:32,936: topic[/rosout] removing connection to /rosout
[rospy.internal][INFO] 2020-02-27 14:50:32,937: topic[/decision_info] removing connection to http://itachi-HP-Pavilion-Laptop-15-cc1xx:41641/
[rospy.impl.masterslave][INFO] 2020-02-27 14:50:32,938: signal-2
[rospy.core][INFO] 2020-02-27 14:50:33,070: signal_shutdown [atexit]
